Workbook

Sheet 5% CO
R1: Component name | S1: Vol % | T1: Carbon number | U1: Class | W1: vol.% * nC | X1: Sel (C base) | Y1: mmolC | Z1: mol
D2: mmolC | E2: mmol C | F2: Conversion | L2: Carbon in Oil | N2: Oil light | O2: Oil heavy | Q2: 1 | R2: Propane | S2: 0.7052 | T2: 3 | U2: paraffin | W2: =S2*T2 -> 2.1156 | X2: =W2/$W$48 -> 0.0027211693 | Y2: =X2*$N$5 -> 0.059651049 | Z2: =Y2/T2 -> 0.019883683 | AG2: mss % | AH2: vol.% * nC | AI2: Sel (C base) | AJ2: mmolC | AK2: mol
D3: IN | E3: OUT | L3: =+D5-E5 -> 31.196366 | N3: 30.233902 | O3: 12.792565 | P3: ml | Q3: 2 | R3: Butene-1 | S3: 4.434 | T3: 4 | U3: Olefin | W3: =S3*T3 -> 17.736 | X3: =W3/$W$48 -> 0.022812752 | Y3: =X3*$N$5 -> 0.50008083 | Z3: =Y3/T3 -> 0.12502021
N4: =+N3/(N3+O3) -> 0.70268149 | O4: =1-N4 -> 0.29731851 | P4: % | Q4: 3 | R4: n-Butane | S4: 0.4237 | T4: 4 | U4: paraffin | W4: =S4*T4 -> 1.6948 | X4: =W4/$W$48 -> 0.0021799195 | Y4: =X4*$N$5 -> 0.047786253 | Z4: =Y4/T4 -> 0.011946563 | AF4: 1 | AG4: 0 | AH4: =AG4*AF4 -> 0 | AI4: =AH4/$AH$54 -> 0 | AJ4: =AI4*$O$5 -> 0 | AK4: =AJ4/AF4 -> 0
C5: TOT | D5: =+D6+D7 -> 217.50474 | E5: =+SUM(E6:E47) -> 186.30837 | G5: mmol | L5: HC Carbon | N5: =+N4*L3 -> 21.921109 | O5: =+O4*L3 -> 9.2752572 | P5: mmcolC | Q5: 4 | R5: i-Butane | S5: 0.2474 | T5: 4 | U5: iso-paraffin | W5: =S5*T5 -> 0.9896 | X5: =W5/$W$48 -> 0.0012728631 | Y5: =X5*$N$5 -> 0.02790257 | Z5: =Y5/T5 -> 0.0069756426 | AF5: 2 | AG5: 0 | AH5: =AG5*AF5 -> 0 | AI5: =AH5/$AH$54 -> 0 | AJ5: =AI5*$O$5 -> 0 | AK5: =AJ5/AF5 -> 0
C6: CO | D6: 52.733113 | E6: 13.424828 | F6: =+(D6-E6)/D6 -> 0.74541939 | L6: =+D7+D6-E6-E7 -> 77.437734 | Q6: 5 | R6: 1,4-Pentadiene | S6: 9.5908 | T6: 5 | U6: Olefin | W6: =S6*T6 -> 47.954 | X6: =W6/$W$48 -> 0.061680352 | Y6: =X6*$N$5 -> 1.3521017 | Z6: =Y6/T6 -> 0.27042034 | AF6: 3 | AG6: 0 | AH6: =AG6*AF6 -> 0 | AI6: =AH6/$AH$54 -> 0 | AJ6: =AI6*$O$5 -> 0 | AK6: =AJ6/AF6 -> 0
B7: 1 | C7: *CO2 | D7: 164.77162 | E7: 126.64217 | F7: =+(D7-E7)/D7 -> 0.23140786 | Q7: 6 | R7: n-Pentane | S7: 0.8438 | T7: 5 | U7: paraffin | W7: =S7*T7 -> 4.219 | X7: =W7/$W$48 -> 0.0054266464 | Y7: =X7*$N$5 -> 0.11895811 | Z7: =Y7/T7 -> 0.023791622 | AF7: 4 | AG7: 0 | AH7: =AG7*AF7 -> 0 | AI7: =AH7/$AH$54 -> 0 | AJ7: =AI7*$O$5 -> 0 | AK7: =AJ7/AF7 -> 0
B8: 8 | C8: Ottene | E8: 0 | G8: =+E8/B8 -> 0 | H8: Olefin | I8: 1 | Q8: 7 | R8: (C5-IsoParaffin) | S8: 0.7139 | T8: 5 | U8: iso-paraffin | W8: =S8*T8 -> 3.5695 | X8: =W8/$W$48 -> 0.0045912336 | Y8: =X8*$N$5 -> 0.10064493 | Z8: =Y8/T8 -> 0.020128986 | AF8: 5 | AG8: 0 | AH8: =AG8*AF8 -> 0 | AI8: =AH8/$AH$54 -> 0 | AJ8: =AI8*$O$5 -> 0 | AK8: =AJ8/AF8 -> 0
B9: 7 | C9: Toluene | E9: 0 | G9: =+E9/B9 -> 0 | H9: Aromatic | I9: 2 | Q9: 8 | R9: Cyclopentane | S9: 0.2986 | T9: 5 | U9: Naphthene | W9: =S9*T9 -> 1.493 | X9: =W9/$W$48 -> 0.0019203563 | Y9: =X9*$N$5 -> 0.042096339 | Z9: =Y9/T9 -> 0.0084192679 | AF9: 6 | AG9: 0 | AH9: =AG9*AF9 -> 0 | AI9: =AH9/$AH$54 -> 0 | AJ9: =AI9*$O$5 -> 0 | AK9: =AJ9/AF9 -> 0
B10: 9 | C10: Nonene | E10: 0.27298184 | G10: =+E10/B10 -> 0.030331315 | H10: Aromatic | I10: 3 | Q10: 9 | R10: 3-Methylpentane | S10: 9.5949 | T10: 6 | U10: iso-paraffin | W10: =S10*T10 -> 57.5694 | X10: =W10/$W$48 -> 0.074048063 | Y10: =X10*$N$5 -> 1.6232157 | Z10: =Y10/T10 -> 0.27053595 | AF10: 7 | AG10: 0 | AH10: =AG10*AF10 -> 0 | AI10: =AH10/$AH$54 -> 0 | AJ10: =AI10*$O$5 -> 0 | AK10: =AJ10/AF10 -> 0
B11: 8 | C11: p-Xilene | E11: 2.1952066e-06 | G11: =+E11/B11 -> 2.7440082e-07 | H11: Aromatic | I11: 4 | Q11: 10 | R11: 1t,4-Hexadiene | S11: 3.8919 | T11: 6 | U11: Olefin | W11: =S11*T11 -> 23.3514 | X11: =W11/$W$48 -> 0.030035504 | Y11: =X11*$N$5 -> 0.65841156 | Z11: =Y11/T11 -> 0.10973526 | AF11: 8 | AG11: 2.5 | AH11: =AG11*AF11 -> 20 | AI11: =AH11/$AH$54 -> 0.013580498 | AJ11: =AI11*$O$5 -> 0.12596262 | AK11: =AJ11/AF11 -> 0.015745327
B12: 8 | C12: m-Xilene | E12: 0.33947952 | G12: =+E12/B12 -> 0.042434939 | H12: Aromatic | I12: 5 | Q12: 11 | R12: Cyclohexane | S12: 0.9641 | T12: 6 | U12: Naphthene | W12: =S12*T12 -> 5.7846 | X12: =W12/$W$48 -> 0.0074403837 | Y12: =X12*$N$5 -> 0.16310146 | Z12: =Y12/T12 -> 0.027183577 | AF12: 9 | AG12: 3.1 | AH12: =AG12*AF12 -> 27.9 | AI12: =AH12/$AH$54 -> 0.018944795 | AJ12: =AI12*$O$5 -> 0.17571785 | AK12: =AJ12/AF12 -> 0.019524205
B13: 8 | C13: Etilbenzene | E13: 0 | G13: =+E13/B13 -> 0 | H13: Aromatic | I13: 6 | Q13: 12 | R13: n-Hexane | S13: 0.109 | T13: 6 | U13: paraffin | W13: =S13*T13 -> 0.654 | X13: =W13/$W$48 -> 0.00084120094 | Y13: =X13*$N$5 -> 0.018440058 | Z13: =Y13/T13 -> 0.0030733429 | AF13: 10 | AG13: 7.9 | AH13: =AG13*AF13 -> 79 | AI13: =AH13/$AH$54 -> 0.053642969 | AJ13: =AI13*$O$5 -> 0.49755233 | AK13: =AJ13/AF13 -> 0.049755233
B14: 8 | C14: o-Xilene | E14: 0 | G14: =+E14/B14 -> 0 | H14: Aromatic | I14: 7 | Q14: 13 | R14: Benzene | S14: 0.08 | T14: 6 | U14: Aromatic | W14: =S14*T14 -> 0.48 | X14: =W14/$W$48 -> 0.00061739519 | Y14: =X14*$N$5 -> 0.013533987 | Z14: =Y14/T14 -> 0.0022556645 | AF14: 11 | AG14: 9.1 | AH14: =AG14*AF14 -> 100.1 | AI14: =AH14/$AH$54 -> 0.067970395 | AJ14: =AI14*$O$5 -> 0.63044289 | AK14: =AJ14/AF14 -> 0.05731299
B15: 9 | C15: Trimetilbenzene | E15: 0 | G15: =+E15/B15 -> 0 | H15: Aromatic | I15: 8 | Q15: 14 | R15: 3-Ethylpentane | S15: 8.1824 | T15: 7 | U15: iso-paraffin | W15: =S15*T15 -> 57.2768 | X15: =W15/$W$48 -> 0.07367171 | Y15: =X15*$N$5 -> 1.6149656 | Z15: =Y15/T15 -> 0.23070937 | AF15: 12 | AG15: 10.5 | AH15: =AG15*AF15 -> 126 | AI15: =AH15/$AH$54 -> 0.08555714 | AJ15: =AI15*$O$5 -> 0.79356448 | AK15: =AJ15/AF15 -> 0.066130373
B16: 10 | C16: Decene | E16: 4.9085231e-06 | G16: =+E16/B16 -> 4.9085231e-07 | H16: Olefin | I16: 9 | Q16: 15 | R16: 2,4-Dimethylpentene-1 | S16: 5.7111 | T16: 7 | U16: Olefin | W16: =S16*T16 -> 39.9777 | X16: =W16/$W$48 -> 0.051420916 | Y16: =X16*$N$5 -> 1.1272035 | Z16: =Y16/T16 -> 0.16102907 | AF16: 13 | AG16: 10.9 | AH16: =AG16*AF16 -> 141.7 | AI16: =AH16/$AH$54 -> 0.096217831 | AJ16: =AI16*$O$5 -> 0.89244513 | AK16: =AJ16/AF16 -> 0.068649625
B17: 10 | C17: Decano | E17: 0.043389939 | G17: =+E17/B17 -> 0.0043389939 | H17: paraffin | I17: 10 | Q17: 16 | R17: 1c,3-Dimethylcyclopentane | S17: 0.8706 | T17: 7 | U17: Naphthene | W17: =S17*T17 -> 6.0942 | X17: =W17/$W$48 -> 0.0078386036 | Y17: =X17*$N$5 -> 0.17183089 | Z17: =Y17/T17 -> 0.024547269 | AF17: 14 | AG17: 10.7 | AH17: =AG17*AF17 -> 149.8 | AI17: =AH17/$AH$54 -> 0.10171793 | AJ17: =AI17*$O$5 -> 0.94345999 | AK17: =AJ17/AF17 -> 0.067389999
B18: 1 | C18: *CH4 | E18: 11.284207 | G18: =+E18/B18 -> 11.284207 | H18: paraffin | I18: 11 | Q18: 17 | R18: Toluene | S18: 0.2139 | T18: 7 | U18: Aromatic | W18: =S18*T18 -> 1.4973 | X18: =W18/$W$48 -> 0.0019258871 | Y18: =X18*$N$5 -> 0.042217581 | Z18: =Y18/T18 -> 0.0060310831 | AF18: 15 | AG18: 9.5 | AH18: =AG18*AF18 -> 142.5 | AI18: =AH18/$AH$54 -> 0.096761051 | AJ18: =AI18*$O$5 -> 0.89748363 | AK18: =AJ18/AF18 -> 0.059832242
B19: 2 | C19: *Etilene | E19: 5.9331212 | G19: =+E19/B19 -> 2.9665606 | H19: Olefin | I19: 12 | Q19: 18 | R19: Octene-1 | S19: 9.3793 | T19: 8 | U19: Olefin | W19: =S19*T19 -> 75.0344 | X19: =W19/$W$48 -> 0.096512245 | Y19: =X19*$N$5 -> 2.1156554 | Z19: =Y19/T19 -> 0.26445693 | AF19: 16 | AG19: 7.7 | AH19: =AG19*AF19 -> 123.2 | AI19: =AH19/$AH$54 -> 0.08365587 | AJ19: =AI19*$O$5 -> 0.77592971 | AK19: =AJ19/AF19 -> 0.048495607
... B43: 7 | C43: 2,2-Dimetilpentano | E43: 6.1570427e-05 | G43: =+E43/B43 -> 8.7957754e-06 | H43: iso-paraffin | I43: 36 | Q43: 42 | R43: (C14-IsoParaffin) | S43: 0.1832 | T43: 14 | U43: iso-paraffin | W43: =S43*T43 -> 2.5648 | X43: =W43/$W$48 -> 0.0032989483 | Y43: =X43*$N$5 -> 0.072316605 | Z43: =Y43/T43 -> 0.0051654718 | AF43: 40 | AG43: 0 | AH43: =AG43*AF43 -> 0 | AI43: =AH43/$AH$54 -> 0 | AJ43: =AI43*$O$5 -> 0 | AK43: =AJ43/AF43 -> 0
B44: 7 | C44: 2-Metiles-1-ene | E44: 0.0004600091 | G44: =+E44/B44 -> 6.5715586e-05 | H44: Olefin | I44: 37 | Q44: 43 | R44: (C15-IsoParaffin) | S44: 0.1445 | T44: 15 | U44: iso-paraffin | W44: =S44*T44 -> 2.1675 | X44: =W44/$W$48 -> 0.0027879251 | Y44: =X44*$N$5 -> 0.061114411 | Z44: =Y44/T44 -> 0.0040742941 | AF44: 48 | AH44: =AG44*AF44 -> 0 | AI44: =AH44/$AH$54 -> 0 | AJ44: =AI44*$O$5 -> 0 | AK44: =AJ44/AF44 -> 0
B45: 7 | C45: 1-eptene | E45: 0.0021357879 | G45: =+E45/B45 -> 0.00030511255 | H45: Olefin | I45: 38 | Q45: 44 | R45: (C16-IsoParaffin) | S45: 0.3685 | T45: 16 | U45: iso-paraffin | W45: =S45*T45 -> 5.896 | X45: =W45/$W$48 -> 0.0075836709 | Y45: =X45*$N$5 -> 0.16624248 | Z45: =Y45/T45 -> 0.010390155 | AF45: 49 | AH45: =AG45*AF45 -> 0 | AI45: =AH45/$AH$54 -> 0 | AJ45: =AI45*$O$5 -> 0 | AK45: =AJ45/AF45 -> 0
B46: 7 | C46: Eptano | E46: 0.00025579855 | G46: =+E46/B46 -> 3.6542649e-05 | H46: paraffin | I46: 39 | Q46: 45 | R46: (C17-IsoParaffin) | S46: 0.1365 | T46: 17 | U46: iso-paraffin | W46: =S46*T46 -> 2.3205 | X46: =W46/$W$48 -> 0.0029847199 | Y46: =X46*$N$5 -> 0.06542837 | Z46: =Y46/T46 -> 0.0038487276 | AF46: 50 | AH46: =AG46*AF46 -> 0 | AI46: =AH46/$AH$54 -> 0 | AJ46: =AI46*$O$5 -> 0 | AK46: =AJ46/AF46 -> 0
B47: 7 | C47: 2-Eptene | E47: 2.7963333e-05 | G47: =+E47/B47 -> 3.9947619e-06 | H47: Olefin | I47: 40 | AF47: 51 | AH47: =AG47*AF47 -> 0 | AI47: =AH47/$AH$54 -> 0 | AJ47: =AI47*$O$5 -> 0 | AK47: =AJ47/AF47 -> 0
B48: 1 | I48: 41 | W48: =SUM(W2:W46) -> 777.4599 | AF48: 52 | AH48: =AG48*AF48 -> 0 | AI48: =AH48/$AH$54 -> 0 | AJ48: =AI48*$O$5 -> 0 | AK48: =AJ48/AF48 -> 0
B49: 1 | I49: 42 | AF49: 53 | AH49: =AG49*AF49 -> 0 | AI49: =AH49/$AH$54 -> 0 | AJ49: =AI49*$O$5 -> 0 | AK49: =AJ49/AF49 -> 0
AF50: 54 | AH50: =AG50*AF50 -> 0 | AI50: =AH50/$AH$54 -> 0 | AJ50: =AI50*$O$5 -> 0 | AK50: =AJ50/AF50 -> 0
AF51: 55 | AH51: =AG51*AF51 -> 0 | AI51: =AH51/$AH$54 -> 0 | AJ51: =AI51*$O$5 -> 0 | AK51: =AJ51/AF51 -> 0
E54: =+SUM(E8:E49) -> 46.241368 | G54: =SUM(G4:G51) -> 22.564836 | Y54: =+SUM(Y1:Y49) -> 21.921109 | Z54: =+SUM(Z1:Z49) -> 2.8195722 | AH54: =SUM(AH4:AH51) -> 1472.7 | AJ54: =SUM(AJ4:AJ51) -> 9.2752572 | AK54: =SUM(AK4:AK51) -> 0.62981308

Sheet 5% CO Elab
Y2: TOT CO | Z2: TOT CO2 | AA2: TOT CO IN | AB2: TOT CO2 IN
B3: Cn | C3: Class | D3: Name | E3: mol | F3: Colonna1 | Y3: ='5% CO'!D6-'5% CO'!E6 -> 39.308285 | Z3: =+'5% CO'!D7-'5% CO'!E7 -> 38.129449 | AA3: =+'5% CO'!D6 -> 52.733113 | AB3: =+'5% CO'!D7 -> 164.77162
B4: ='5% CO'!B25 -> 1 | C4: ='5% CO'!H25 -> oxygenated | D4: ='5% CO'!C25 -> Metanolo | E4: ='5% CO'!G25 -> 0.64499028 | F4: 1-GAS | Y4: =Y3/(Y3+Z3) -> 0.50761151 | Z4: =1-Y4 -> 0.49238849
B5: ='5% CO'!B18 -> 1 | C5: ='5% CO'!H18 -> paraffin | D5: ='5% CO'!C18 -> *CH4 | E5: ='5% CO'!G18 -> 11.284207 | F5: 1-GAS | R5: Colonna1 | S5: Nc | T5: Colonna2 | U5: Colonna3 | V5: Colonna4 | W5: mmol | X5: mmolC | Y5: Colonna5 | Z5: Colonna6 | AA5: con CO | AB5: conv CO2 | AH5: Etichette di riga | AI5: Somma di mmolC
B6: ='5% CO'!B20 -> 2 | C6: ='5% CO'!H20 -> Olefin | D6: ='5% CO'!C20 -> *Acetilene | E6: ='5% CO'!G20 -> 0 | F6: 1-GAS | R6: 1 | S6: 1 | T6: METHANE | U6: CH4 | V6: CH4 | W6: =GETPIVOTDATA("mol",$N$17,"Cn",1,"Class","paraffin") -> 11.284207 | X6: =+W6*S6 -> 11.284207 | Y6: =X6*$Y$4 -> 5.7279936 | Z6: =+X6*$Z$4 -> 5.5562139 | AA6: =+Y6/$AA$3 -> 0.10862233 | AB6: =+Z6/$AB$3 -> 0.033720697 | AD6: =+$AB$3*Tabella11[[#This Row],[conv CO2]] -> 5.5562139 | AH6: 1 | AI6: 11.929198
B7: ='5% CO'!B19 -> 2 | C7: ='5% CO'!H19 -> Olefin | D7: ='5% CO'!C19 -> *Etilene | E7: ='5% CO'!G19 -> 2.9665606 | F7: 1-GAS | R7: 2 | S7: 1 | T7: METHANOL | U7: CH4O | V7: MEOH | W7: =+GETPIVOTDATA("mol",$N$17,"Cn",1,"Class","oxygenated") -> 0.64499028 | X7: =+W7*S7 -> 0.64499028 | Y7: =X7*$Y$4 -> 0.32740449 | Z7: =+X7*$Z$4 -> 0.31758579 | AA7: =+Y7/$AA$3 -> 0.0062087078 | AB7: =+Z7/$AB$3 -> 0.0019274301 | AD7: =+$AB$3*Tabella11[[#This Row],[conv CO2]] -> 0.31758579 | AH7: 2 | AI7: 7.4382037
B8: ='5% CO'!B24 -> 2 | C8: ='5% CO'!H24 -> oxygenated | D8: ='5% CO'!C24 -> *DME | E8: ='5% CO'!G24 -> 0 | F8: 1-GAS | R8: 3 | S8: 2 | T8: ETHANE | U8: C2H6 | V8: C2 | W8: =+GETPIVOTDATA("mol",$N$17,"Cn",2,"Class","paraffin") -> 0.75254128 | X8: =+W8*S8 -> 1.5050826 | Y8: =X8*$Y$4 -> 0.76399723 | Z8: =+X8*$Z$4 -> 0.74108532 | AA8: =+Y8/$AA$3 -> 0.014487998 | AB8: =+Z8/$AB$3 -> 0.0044976514 | AD8: =+$AB$3*Tabella11[[#This Row],[conv CO2]] -> 0.74108532 | AH8: 3 | AI8: 9.9256945
B9: ='5% CO'!B21 -> 2 | C9: ='5% CO'!H21 -> paraffin | D9: ='5% CO'!C21 -> *Etano | E9: ='5% CO'!G21 -> 0.75254128 | F9: 1-GAS | R9: 4 | S9: 2 | T9: ETHYLENE | U9: C2H4 | V9: C2-O | W9: =+GETPIVOTDATA("mol",$N$17,"Cn",2,"Class","Olefin") -> 2.9665606 | X9: =+W9*S9 -> 5.9331212 | Y9: =X9*$Y$4 -> 3.0117206 | Z9: =+X9*$Z$4 -> 2.9214006 | AA9: =+Y9/$AA$3 -> 0.057112513 | AB9: =+Z9/$AB$3 -> 0.017729998 | AH9: 4 | AI9: 8.0172348
B10: ='5% CO'!B22 -> 3 | C10: ='5% CO'!H22 -> Olefin | D10: ='5% CO'!C22 -> *Propilene | E10: ='5% CO'!G22 -> 2.9824519 | F10: 1-GAS | R10: 5 | S10: 3 | T10: PROPANE | U10: C3H8 | V10: C3 | W10: =+GETPIVOTDATA("mol",$N$17,"Cn",3,"Class","paraffin") -> 0.32611294 | X10: =+W10*S10 -> 0.97833881 | Y10: =X10*$Y$4 -> 0.49661604 | Z10: =+X10*$Z$4 -> 0.48172277 | AA10: =+Y10/$AA$3 -> 0.009417537 | AB10: =+Z10/$AB$3 -> 0.0029235785 | AH10: 5 | AI10: 7.7743977
B11: ='5% CO'!B23 -> 3 | C11: ='5% CO'!H23 -> paraffin | D11: ='5% CO'!C23 -> *Propano | E11: ='5% CO'!G23 -> 0.30622926 | F11: 1-GAS | R11: 6 | S11: 3 | T11: PROPYLENE | U11: C3H6-2 | V11: C3-O | W11: =+GETPIVOTDATA("mol",$N$17,"Cn",3,"Class","Olefin") -> 2.9824519 | X11: =+W11*S11 -> 8.9473557 | Y11: =X11*$Y$4 -> 4.5417808 | Z11: =+X11*$Z$4 -> 4.405575 | AA11: =+Y11/$AA$3 -> 0.086127681 | AB11: =+Z11/$AB$3 -> 0.026737462 | AH11: 6 | AI11: 5.2237641
B12: ='5% CO'!B27 -> 4 | C12: ='5% CO'!H27 -> Olefin | D12: ='5% CO'!C27 -> *1-Butene | E12: ='5% CO'!G27 -> 1.5864331 | F12: 1-GAS | R12: 7 | S12: 4 | T12: N-BUTANE | U12: C4H10-1 | V12: C4 | W12: =+GETPIVOTDATA("mol",$N$17,"Cn",4,"Class","paraffin") -> 0.23449561 | X12: =+W12*S12 -> 0.93798244 | Y12: =X12*$Y$4 -> 0.47613068 | Z12: =+X12*$Z$4 -> 0.46185176 | AA12: =+Y12/$AA$3 -> 0.0090290646 | AB12: =+Z12/$AB$3 -> 0.0028029812 | AH12: 7 | AI12: 2.9591587
B13: ='5% CO'!B29 -> 4 | C13: ='5% CO'!H29 -> Olefin | D13: ='5% CO'!C29 -> 2-Butene | E13: ='5% CO'!G29 -> 0.02835486 | F13: 1-GAS | R13: 8 | S13: 4 | T13: ISOBUTANE | U13: C4H10-2 | V13: C4-IP | W13: =+GETPIVOTDATA("mol",$N$17,"Cn",4,"Class","iso-paraffin") -> 0.0069756426 | X13: =+W13*S13 -> 0.02790257 | Y13: =X13*$Y$4 -> 0.014163666 | Z13: =+X13*$Z$4 -> 0.013738904 | AA13: =+Y13/$AA$3 -> 0.0002685915 | AB13: =+Z13/$AB$3 -> 8.3381497e-05 | AH13: 8 | AI13: 4.1037636
B14: ='5% CO'!B26 -> 4 | C14: ='5% CO'!H26 -> Olefin | D14: ='5% CO'!C26 -> 2-Metilpropene | E14: ='5% CO'!G26 -> 0.023029278 | F14: 1-GAS | R14: 9 | S14: 4 | T14: 1-BUTENE | U14: C4H8-1 | V14: C4-O | W14: =+GETPIVOTDATA("mol",$N$17,"Cn",4,"Class","Olefin") -> 1.7628374 | X14: =+W14*S14 -> 7.0513498 | Y14: =X14*$Y$4 -> 3.5793463 | Z14: =+X14*$Z$4 -> 3.4720035 | AA14: =+Y14/$AA$3 -> 0.067876636 | AB14: =+Z14/$AB$3 -> 0.021071611 | AH14: 9 | AI14: 4.1587801
B15: ='5% CO'!B28 -> 4 | C15: ='5% CO'!H28 -> paraffin | D15: ='5% CO'!C28 -> *N-Butano | E15: ='5% CO'!G28 -> 0.22254905 | F15: 1-GAS | R15: 10 | S15: 5 | T15: N-PENTANE | U15: C5H12-1 | V15: C5 | W15: =+GETPIVOTDATA("mol",$N$17,"Cn",5,"Class","paraffin") -> 0.15138393 | X15: =+W15*S15 -> 0.75691963 | Y15: =X15*$Y$4 -> 0.38422112 | Z15: =+X15*$Z$4 -> 0.37269851 | AA15: =+Y15/$AA$3 -> 0.0072861452 | AB15: =+Z15/$AB$3 -> 0.0022619096 | AH15: 10 | AI15: 3.5567425
B16: ='5% CO'!B31 -> 5 | C16: ='5% CO'!H31 -> iso-paraffin | D16: ='5% CO'!C31 -> 2-Metilbutano | E16: ='5% CO'!G31 -> 0 | F16: 1-GAS | R16: 11 | S16: 5 | T16: 2-METHYL-1-BUTANE | U16: C5H12-5 | V16: C5-IP | W16: =+GETPIVOTDATA("mol",$N$17,"Cn",5,"Class","iso-paraffin") -> 0.020128986 | X16: =+W16*S16 -> 0.10064493 | Y16: =X16*$Y$4 -> 0.051088526 | Z16: =+X16*$Z$4 -> 0.049556406 | AA16: =+Y16/$AA$3 -> 0.00096881301 | AB16: =+Z16/$AB$3 -> 0.00030075814 | AH16: 11 | AI16: 2.6618577
B17: ='5% CO'!B33 -> 5 | C17: ='5% CO'!H33 -> Olefin | D17: ='5% CO'!C33 -> *1-Pentene | E17: ='5% CO'!G33 -> 0.87794252 | F17: 1-GAS | N17: Cn | O17: Class | P17: Somma di mol | R17: 12 | S17: 5 | T17: 1-PENTENE | U17: C5H10-2 | V17: C5-O | W17: =+GETPIVOTDATA("mol",$N$17,"Cn",5,"Class","Olefin") -> 1.3749474 | X17: =+W17*S17 -> 6.8747368 | Y17: =X17*$Y$4 -> 3.4896955 | Z17: =+X17*$Z$4 -> 3.3850413 | AA17: =+Y17/$AA$3 -> 0.066176551 | AB17: =+Z17/$AB$3 -> 0.020543836 | AH17: 12 | AI17: 1.9510926
B18: ='5% CO'!B32 -> 5 | C18: ='5% CO'!H32 -> Olefin | D18: ='5% CO'!C32 -> 2-Metilbut-1-ene | E18: ='5% CO'!G32 -> 0 | F18: 1-GAS | N18: 1 | O18: oxygenated | P18: 0.64499028 | R18: 13 | S18: 5 | T18: CYCLOPENTANE | V18: C5-N | W18: =+GETPIVOTDATA("mol",$N$17,"Cn",5,"Class","Naphthene") -> 0.0084192679 | X18: =+W18*S18 -> 0.042096339 | Y18: =X18*$Y$4 -> 0.021368586 | Z18: =+X18*$Z$4 -> 0.020727753 | AA18: =+Y18/$AA$3 -> 0.00040522141 | AB18: =+Z18/$AB$3 -> 0.00012579686 | AH18: 13 | AI18: 1.2131724
B19: ='5% CO'!B34 -> 5 | C19: ='5% CO'!H34 -> Olefin | D19: ='5% CO'!C34 -> 2-Pentene | E19: ='5% CO'!G34 -> 0 | F19: 1-GAS | N19: 1 | O19: paraffin | P19: 11.284207 | R19: 14 | S19: 6 | T19: 2,2-DIMETHYL-BUTANE | U19: C6H14-4 | V19: C6-IP | W19: =+GETPIVOTDATA("mol",$N$17,"Cn",6,"Class","iso-paraffin") -> 0.41390825 | X19: =+W19*S19 -> 2.4834495 | Y19: =X19*$Y$4 -> 1.2606276 | Z19: =+X19*$Z$4 -> 1.222822 | AA19: =+Y19/$AA$3 -> 0.023905806 | AB19: =+Z19/$AB$3 -> 0.0074213141 | AH19: 14 | AI19: 1.0157766
B20: ='5% CO'!B30 -> 5 | C20: ='5% CO'!H30 -> Olefin | D20: ='5% CO'!C30 -> 3-Metilbut-1-ene | E20: ='5% CO'!G30 -> 0.2265845 | F20: 1-GAS | N20: 2 | O20: Olefin | P20: 2.9665606 | R20: 15 | S20: 6 | T20: N-HEXANE | U20: C6H14-1 | V20: C6 | W20: =+GETPIVOTDATA("mol",$N$17,"Cn",6,"Class","paraffin") -> 0.0050046801 | X20: =+W20*S20 -> 0.03002808 | Y20: =X20*$Y$4 -> 0.015242599 | Z20: =+X20*$Z$4 -> 0.014785481 | AA20: =+Y20/$AA$3 -> 0.00028905176 | AB20: =+Z20/$AB$3 -> 8.9733177e-05 | AH20: 15 | AI20: 0.95859804
B21: ='5% CO'!B35 -> 5 | C21: ='5% CO'!H35 -> paraffin | D21: ='5% CO'!C35 -> *Pentano | E21: ='5% CO'!G35 -> 0.12759231 | F21: 1-GAS | N21: 2 | O21: oxygenated | P21: 0 | R21: 16 | S21: 6 | T21: 2-METHYL-1-PENTENE | U21: C6H12-D2 | V21: C6-O | W21: =+GETPIVOTDATA("mol",$N$17,"Cn",6,"Class","Olefin") -> 0.42227517 | X21: =+W21*S21 -> 2.533651 | Y21: =X21*$Y$4 -> 1.2861104 | Z21: =+X21*$Z$4 -> 1.2475406 | AA21: =+Y21/$AA$3 -> 0.024389048 | AB21: =+Z21/$AB$3 -> 0.0075713317 | AH21: 16 | AI21: 0.94217219
B22: ='5% CO'!B37 -> 6 | C22: ='5% CO'!H37 -> iso-paraffin | D22: ='5% CO'!C37 -> 2,2-Dimetilbutano | E22: ='5% CO'!G37 -> 0.14337231 | F22: 1-GAS | N22: 2 | O22: paraffin | P22: 0.75254128 | R22: 17 | S22: 6 | T22: BENZENE | V22: C6-A | W22: =+GETPIVOTDATA("mol",$N$17,"Cn",6,"Class","Aromatic") -> 0.0022556645 | X22: =+W22*S22 -> 0.013533987 | Y22: =X22*$Y$4 -> 0.0068700077 | Z22: =+X22*$Z$4 -> 0.0066639795 | AA22: =+Y22/$AA$3 -> 0.00013027882 | AB22: =+Z22/$AB$3 -> 4.0443733e-05 | AH22: 17 | AI22: 0.78278546
B23: ='5% CO'!B40 -> 6 | C23: ='5% CO'!H40 -> Olefin | D23: ='5% CO'!C40 -> 1-Esene | E23: ='5% CO'!G40 -> 1.9141242e-05 | F23: 1-GAS | N23: 3 | O23: Olefin | P23: 2.9824519 | R23: 18 | S23: 6 | T23: CYCLOHEXANE | V23: C6-N | W23: =+GETPIVOTDATA("mol",$N$17,"Cn",6,"Class","Naphthene") -> 0.027183577 | X23: =+W23*S23 -> 0.16310146 | Y23: =X23*$Y$4 -> 0.08279218 | Z23: =+X23*$Z$4 -> 0.080309283 | AA23: =+Y23/$AA$3 -> 0.0015700226 | AB23: =+Z23/$AB$3 -> 0.00048739754 | AH23: 18 | AI23: 0.70287139
B24: ='5% CO'!B36 -> 6 | C24: ='5% CO'!H36 -> Olefin | D24: ='5% CO'!C36 -> 2-Metilbut-2-ene | E24: ='5% CO'!G36 -> 0.010782087 | F24: 1-GAS | N24: 3 | O24: paraffin | P24: 0.32611294 | R24: 19 | S24: 7 | T24: N-HEPTANE | U24: C7H16-1 | V24: C7 | W24: =+GETPIVOTDATA("mol",$N$17,"Cn",7,"Class","paraffin") -> 3.6542649e-05 | X24: =+W24*S24 -> 0.00025579855 | Y24: =X24*$Y$4 -> 0.00012984629 | Z24: =+X24*$Z$4 -> 0.00012595226 | AA24: =+Y24/$AA$3 -> 2.4623292e-06 | AB24: =+Z24/$AB$3 -> 7.6440505e-07 | AH24: 19 | AI24: 0.33506056
B25: ='5% CO'!B42 -> 6 | C25: ='5% CO'!H42 -> Olefin | D25: ='5% CO'!C42 -> 2,3-Dimetilbut-2-ene | E25: ='5% CO'!G42 -> 2.3569675e-05 | F25: 1-GAS | N25: 4 | O25: iso-paraffin | P25: 0.0069756426 | R25: 20 | S25: 7 | T25: 2-METHYLHEXANE | U25: C7H16-2 | V25: C7-IP | W25: =+GETPIVOTDATA("mol",$N$17,"Cn",7,"Class","iso-paraffin") -> 0.23071816 | X25: =+W25*S25 -> 1.6150272 | Y25: =X25*$Y$4 -> 0.81980637 | Z25: =+X25*$Z$4 -> 0.79522078 | AA25: =+Y25/$AA$3 -> 0.01554633 | AB25: =+Z25/$AB$3 -> 0.0048261999 | AH25: 20 | AI25: 0.27711775
B26: ='5% CO'!B38 -> 6 | C26: ='5% CO'!H38 -> Olefin | D26: ='5% CO'!C38 -> 3-Metilpent-1-ene | E26: ='5% CO'!G38 -> 0 | F26: 1-GAS | N26: 4 | O26: Olefin | P26: 1.7628374 | R26: 21 | S26: 7 | T26: 1-HEPTENE | U26: C7H14-7 | V26: C7-O | W26: =+GETPIVOTDATA("mol",$N$17,"Cn",7,"Class","Olefin") -> 0.16140389 | X26: =+W26*S26 -> 1.1298273 | Y26: =X26*$Y$4 -> 0.57351332 | Z26: =+X26*$Z$4 -> 0.55631394 | AA26: =+Y26/$AA$3 -> 0.010875772 | AB26: =+Z26/$AB$3 -> 0.0033762728 | AH26: 21 | AI26: 0.26452149
B27: ='5% CO'!B39 -> 6 | C27: ='5% CO'!H39 -> Olefin | D27: ='5% CO'!C39 -> 4-Metilpent-2-ene | E27: ='5% CO'!G39 -> 0.30171511 | F27: 1-GAS | N27: 4 | O27: paraffin | P27: 0.23449561 | R27: 22 | S27: 7 | T27: TOLUENE | U27: C7H8 | V27: C7-A | W27: =+GETPIVOTDATA("mol",$N$17,"Cn",7,"Class","Aromatic") -> 0.0060310831 | X27: =+W27*S27 -> 0.042217581 | Y27: =X27*$Y$4 -> 0.02143013 | Z27: =+X27*$Z$4 -> 0.020787451 | AA27: =+Y27/$AA$3 -> 0.00040638849 | AB27: =+Z27/$AB$3 -> 0.00012615917 | AH27: 22 | AI27: 0.24940598
B28: ='5% CO'!B41 -> 6 | C28: ='5% CO'!H41 -> paraffin | D28: ='5% CO'!C41 -> Esano | E28: ='5% CO'!G41 -> 0.0019313371 | F28: 1-GAS | N28: 5 | O28: iso-paraffin | P28: 0.020128986 | R28: 23 | S28: 7 | T28: 1c,3-Dimethylcyclopentane | V28: C7-N | W28: =+GETPIVOTDATA("mol",$N$17,"Cn",7,"Class","Naphthene") -> 0.024547269 | X28: =+W28*S28 -> 0.17183089 | Y28: =X28*$Y$4 -> 0.087223335 | Z28: =+X28*$Z$4 -> 0.08460755 | AA28: =+Y28/$AA$3 -> 0.0016540525 | AB28: =+Z28/$AB$3 -> 0.00051348375 | AH28: 23 | AI28: 0.23177121
B29: ='5% CO'!B9 -> 7 | C29: ='5% CO'!H9 -> Aromatic | D29: ='5% CO'!C9 -> Toluene | E29: ='5% CO'!G9 -> 0 | F29: 1-GAS | N29: 5 | O29: Naphthene | P29: 0.0084192679 | R29: 24 | S29: 8 | T29: N-OCTANE | U29: C8H18-1 | V29: C8 | W29: =+GETPIVOTDATA("mol",$N$17,"Cn",8,"Class","paraffin") -> 0.016684247 | X29: =+W29*S29 -> 0.13347398 | Y29: =X29*$Y$4 -> 0.067752928 | Z29: =+X29*$Z$4 -> 0.06572105 | AA29: =+Y29/$AA$3 -> 0.001284827 | AB29: =+Z29/$AB$3 -> 0.00039886146 | AH29: 24 | AI29: 0.22673271
B30: ='5% CO'!B43 -> 7 | C30: ='5% CO'!H43 -> iso-paraffin | D30: ='5% CO'!C43 -> 2,2-Dimetilpentano | E30: ='5% CO'!G43 -> 8.7957754e-06 | F30: 1-GAS | N30: 5 | O30: Olefin | P30: 1.3749474 | R30: 25 | S30: 8 | T30: 2,2,4-TRIMETHYLPENTANE | U30: C8H18-13 | V30: C8-IP | W30: =+GETPIVOTDATA("mol",$N$17,"Cn",8,"Class","iso-paraffin") -> 0.096330974 | X30: =+W30*S30 -> 0.77064779 | Y30: =X30*$Y$4 -> 0.39118969 | Z30: =+X30*$Z$4 -> 0.3794581 | AA30: =+Y30/$AA$3 -> 0.0074182931 | AB30: =+Z30/$AB$3 -> 0.0023029336 | AH30: 25 | AI30: 0.20468925
B31: ='5% CO'!B45 -> 7 | C31: ='5% CO'!H45 -> Olefin | D31: ='5% CO'!C45 -> 1-eptene | E31: ='5% CO'!G45 -> 0.00030511255 | F31: 1-GAS | N31: 5 | O31: paraffin | P31: 0.15138393 | R31: 26 | S31: 8 | T31: 1-OCTENE | U31: C8H16-16 | V31: C8-O | W31: =+GETPIVOTDATA("mol",$N$17,"Cn",8,"Class","Olefin") -> 0.26445693 | X31: =+W31*S31 -> 2.1156554 | Y31: =X31*$Y$4 -> 1.0739311 | Z31: =+X31*$Z$4 -> 1.0417244 | AA31: =+Y31/$AA$3 -> 0.020365402 | AB31: =+Z31/$AB$3 -> 0.0063222318 | AH31: 26 | AI31: 0.18012654
B32: ='5% CO'!B47 -> 7 | C32: ='5% CO'!H47 -> Olefin | D32: ='5% CO'!C47 -> 2-Eptene | E32: ='5% CO'!G47 -> 3.9947619e-06 | F32: 1-GAS | N32: 6 | O32: Aromatic | P32: 0.0022556645 | R32: 27 | S32: 8 | T32: 1-METHYL-1-ETHYLCYCLOPENTANE | U32: C8H16-13 | V32: C8-N | W32: =+GETPIVOTDATA("mol",$N$17,"Cn",8,"Class","Naphthene") -> 0.043241089 | X32: =+W32*S32 -> 0.34592871 | Y32: =X32*$Y$4 -> 0.1755974 | Z32: =+X32*$Z$4 -> 0.17033132 | AA32: =+Y32/$AA$3 -> 0.0033299266 | AB32: =+Z32/$AB$3 -> 0.0010337418 | AH32: 27 | AI32: 0.15304458
B33: ='5% CO'!B44 -> 7 | C33: ='5% CO'!H44 -> Olefin | D33: ='5% CO'!C44 -> 2-Metiles-1-ene | E33: ='5% CO'!G44 -> 6.5715586e-05 | F33: 1-GAS | N33: 6 | O33: iso-paraffin | P33: 0.41390825 | R33: 28 | S33: 8 | T33: M-XYLENE | U33: C8H10-2 | V33: C8-A | W33: =+GETPIVOTDATA("mol",$N$17,"Cn",8,"Class","Aromatic") -> 0.092257204 | X33: =+W33*S33 -> 0.73805764 | Y33: =X33*$Y$4 -> 0.37464655 | Z33: =+X33*$Z$4 -> 0.36341108 | AA33: =+Y33/$AA$3 -> 0.0071045787 | AB33: =+Z33/$AB$3 -> 0.0022055441 | AH33: Totale complessivo | AI33: 77.437734
B34: ='5% CO'!B46 -> 7 | C34: ='5% CO'!H46 -> paraffin | D34: ='5% CO'!C46 -> Eptano | E34: ='5% CO'!G46 -> 3.6542649e-05 | F34: 1-GAS | N34: 6 | O34: Naphthene | P34: 0.027183577 | R34: 29 | S34: 9 | T34: N-NONANE | U34: C9H20-1 | V34: C9 | W34: =+GETPIVOTDATA("mol",$N$17,"Cn",9,"Class","paraffin") -> 0.039737779 | X34: =+W34*S34 -> 0.35764001 | Y34: =X34*$Y$4 -> 0.18154219 | Z34: =+X34*$Z$4 -> 0.17609783 | AA34: =+Y34/$AA$3 -> 0.0034426601 | AB34: =+Z34/$AB$3 -> 0.0010687388
B35: ='5% CO'!B13 -> 8 | C35: ='5% CO'!H13 -> Aromatic | D35: ='5% CO'!C13 -> Etilbenzene | E35: ='5% CO'!G13 -> 0 | F35: 1-GAS | N35: 6 | O35: Olefin | P35: 0.42227517 | R35: 30 | S35: 9 | T35: 3-METHYLOCTANE | U35: C9H20-D2 | V35: C9-IP | W35: =+GETPIVOTDATA("mol",$N$17,"Cn",9,"Class","iso-paraffin") -> 0.25327729 | X35: =+W35*S35 -> 2.2794956 | Y35: =X35*$Y$4 -> 1.1570982 | Z35: =+X35*$Z$4 -> 1.1223974 | AA35: =+Y35/$AA$3 -> 0.021942536 | AB35: =+Z35/$AB$3 -> 0.0068118369
B36: ='5% CO'!B12 -> 8 | C36: ='5% CO'!H12 -> Aromatic | D36: ='5% CO'!C12 -> m-Xilene | E36: ='5% CO'!G12 -> 0.042434939 | F36: 1-GAS | N36: 6 | O36: paraffin | P36: 0.0050046801 | R36: 31 | S36: 9 | T36: 1-NONENE | U36: C9H18-3 | V36: C9-O | W36: =+GETPIVOTDATA("mol",$N$17,"Cn",9,"Class","Olefin") -> 0.046675338 | X36: =+W36*S36 -> 0.42007805 | Y36: =X36*$Y$4 -> 0.21323645 | Z36: =+X36*$Z$4 -> 0.20684159 | AA36: =+Y36/$AA$3 -> 0.0040436917 | AB36: =+Z36/$AB$3 -> 0.0012553229
B37: ='5% CO'!B14 -> 8 | C37: ='5% CO'!H14 -> Aromatic | D37: ='5% CO'!C14 -> o-Xilene | E37: ='5% CO'!G14 -> 0 | F37: 1-GAS | N37: 7 | O37: Aromatic | P37: 0.0060310831 | R37: 32 | S37: 9 | T37: ISOPROPYLCYCLOHEXANE | U37: C9H18-2 | V37: C9-N | W37: =+GETPIVOTDATA("mol",$N$17,"Cn",9,"Class","Naphthene") -> 0.026312327 | X37: =+W37*S37 -> 0.23681094 | Y37: =X37*$Y$4 -> 0.12020796 | Z37: =+X37*$Z$4 -> 0.11660298 | AA37: =+Y37/$AA$3 -> 0.0022795536 | AB37: =+Z37/$AB$3 -> 0.00070766422
B38: ='5% CO'!B11 -> 8 | C38: ='5% CO'!H11 -> Aromatic | D38: ='5% CO'!C11 -> p-Xilene | E38: ='5% CO'!G11 -> 2.7440082e-07 | F38: 1-GAS | N38: 7 | O38: iso-paraffin | P38: 0.23071816 | R38: 33 | S38: 9 | T38: INDANE | U38: C9H10-E1 | V38: C9-A | W38: =+GETPIVOTDATA("mol",$N$17,"Cn",9,"Class","Aromatic") -> 0.096083937 | X38: =+W38*S38 -> 0.86475543 | Y38: =X38*$Y$4 -> 0.43895981 | Z38: =+X38*$Z$4 -> 0.42579562 | AA38: =+Y38/$AA$3 -> 0.0083241778 | AB38: =+Z38/$AB$3 -> 0.0025841563
B39: ='5% CO'!B8 -> 8 | C39: ='5% CO'!H8 -> Olefin | D39: ='5% CO'!C8 -> Ottene | E39: ='5% CO'!G8 -> 0 | F39: 1-GAS | N39: 7 | O39: Naphthene | P39: 0.024547269 | R39: 34 | S39: 10 | T39: N-DECANE | U39: C10H22-1 | V39: C10 | W39: =+GETPIVOTDATA("mol",$N$17,"Cn",10,"Class","paraffin") -> 0.054094227 | X39: =+W39*S39 -> 0.54094227 | Y39: =X39*$Y$4 -> 0.27458852 | Z39: =+X39*$Z$4 -> 0.26635375 | AA39: =+Y39/$AA$3 -> 0.0052071366 | AB39: =+Z39/$AB$3 -> 0.0016165025
B40: ='5% CO'!B10 -> 9 | C40: ='5% CO'!H10 -> Aromatic | D40: ='5% CO'!C10 -> Nonene | E40: ='5% CO'!G10 -> 0.030331315 | F40: 1-GAS | N40: 7 | O40: Olefin | P40: 0.16140389 | R40: 35 | S40: 10 | T40: 2-METHYLNONANE | U40: C10H22-E2 | V40: C10-IP | W40: =+GETPIVOTDATA("mol",$N$17,"Cn",10,"Class","iso-paraffin") -> 0.086098715 | X40: =+W40*S40 -> 0.86098715 | Y40: =X40*$Y$4 -> 0.43704699 | Z40: =+X40*$Z$4 -> 0.42394016 | AA40: =+Y40/$AA$3 -> 0.0082879042 | AB40: =+Z40/$AB$3 -> 0.0025728955
B41: ='5% CO'!B15 -> 9 | C41: ='5% CO'!H15 -> Aromatic | D41: ='5% CO'!C15 -> Trimetilbenzene | E41: ='5% CO'!G15 -> 0 | F41: 1-GAS | N41: 7 | O41: paraffin | P41: 3.6542649e-05 | R41: 36 | S41: 10 | T41: 1-DECENE | U41: C10H20-5 | V41: C10-O | W41: =+GETPIVOTDATA("mol",$N$17,"Cn",10,"Class","Olefin") -> 0.093934821 | X41: =+W41*S41 -> 0.93934821 | Y41: =X41*$Y$4 -> 0.47682396 | Z41: =+X41*$Z$4 -> 0.46252425 | AA41: =+Y41/$AA$3 -> 0.0090422115 | AB41: =+Z41/$AB$3 -> 0.0028070625
...

Sheet 10% CO
R1: Component name | S1: Vol % | T1: Carbon number | U1: Class | V1: Colonna1 | W1: vol.% * nC | X1: Sel (C base) | Y1: mmolC | Z1: mol
D2: mmolC | E2: mmol C | F2: Conversion | L2: Carbon in Oil | N2: Oil light | O2: Oil heavy | R2: Propane | S2: 0.7052 | T2: 3 | U2: paraffin | V2: 1 | W2: =S2*T2 -> 2.1156 | X2: =W2/$W$48 -> 0.0027211693 | Y2: =X2*$N$5 -> 0.065834288 | Z2: =Y2/T2 -> 0.021944763 | AG2: mss % | AH2: vol.% * nC | AI2: Sel (C base) | AJ2: mmolC | AK2: mol
D3: IN | E3: OUT | L3: =+D5-E5 -> 38.34203 | N3: 27 | O3: 15.79 | P3: ml | R3: Butene-1 | S3: 4.434 | T3: 4 | U3: Olefin | V3: 2 | W3: =S3*T3 -> 17.736 | X3: =W3/$W$48 -> 0.022812752 | Y3: =X3*$N$5 -> 0.55191762 | Z3: =Y3/T3 -> 0.13797941
N4: =+N3/(N3+O3) -> 0.63098855 | O4: =1-N4 -> 0.36901145 | P4: % | R4: n-Butane | S4: 0.4237 | T4: 4 | U4: paraffin | V4: 3 | W4: =S4*T4 -> 1.6948 | X4: =W4/$W$48 -> 0.0021799195 | Y4: =X4*$N$5 -> 0.052739625 | Z4: =Y4/T4 -> 0.013184906 | AF4: 1 | AG4: 0 | AH4: =AG4*AF4 -> 0 | AI4: =AH4/$AH$54 -> 0 | AJ4: =AI4*$O$5 -> 0 | AK4: =AJ4/AF4 -> 0
C5: TOT | D5: =+D6+D7 -> 208.88612 | E5: =SUM(E6:E47) -> 170.54409 | G5: mmol | L5: HC Carbon | N5: =+N4*L3 -> 24.193382 | O5: =+O4*L3 -> 14.148648 | P5: mmcolC | R5: i-Butane | S5: 0.2474 | T5: 4 | U5: iso-paraffin | V5: 4 | W5: =S5*T5 -> 0.9896 | X5: =W5/$W$48 -> 0.0012728631 | Y5: =X5*$N$5 -> 0.030794862 | Z5: =Y5/T5 -> 0.0076987156 | AF5: 2 | AG5: 0 | AH5: =AG5*AF5 -> 0 | AI5: =AH5/$AH$54 -> 0 | AJ5: =AI5*$O$5 -> 0 | AK5: =AJ5/AF5 -> 0
C6: CO | D6: 84.481827 | E6: 8.8726193 | F6: =+(D6-E6)/D6 -> 0.894976 | G6: =+(D6+D7-E7-E6)/(D6+D7) -> 0.44385286 | J6: =+E6*$L$24 -> 8.1442642 | L6: =+D7+D6-E6-E7 -> 92.714701 | R6: 1,4-Pentadiene | S6: 9.5908 | T6: 5 | U6: Olefin | V6: 5 | W6: =S6*T6 -> 47.954 | X6: =W6/$W$48 -> 0.061680352 | Y6: =X6*$N$5 -> 1.4922563 | Z6: =Y6/T6 -> 0.29845126 | AF6: 3 | AG6: 0 | AH6: =AG6*AF6 -> 0 | AI6: =AH6/$AH$54 -> 0 | AJ6: =AI6*$O$5 -> 0 | AK6: =AJ6/AF6 -> 0
B7: 1 | C7: *CO2 | D7: 124.40429 | E7: 107.2988 | F7: =+(D7-E7)/D7 -> 0.13749922 | J7: =+E7*$L$24 -> 98.490617 | R7: n-Pentane | S7: 0.8438 | T7: 5 | U7: paraffin | V7: 6 | W7: =S7*T7 -> 4.219 | X7: =W7/$W$48 -> 0.0054266464 | Y7: =X7*$N$5 -> 0.13128893 | Z7: =Y7/T7 -> 0.026257786 | AF7: 4 | AG7: 0 | AH7: =AG7*AF7 -> 0 | AI7: =AH7/$AH$54 -> 0 | AJ7: =AI7*$O$5 -> 0 | AK7: =AJ7/AF7 -> 0
B8: 8 | C8: Ottene | E8: 0 | G8: =+E8/B8 -> 0 | H8: Olefin | I8: 1 | J8: =+E8*$L$24 -> 0 | R8: (C5-IsoParaffin) | S8: 0.7139 | T8: 5 | U8: iso-paraffin | V8: 7 | W8: =S8*T8 -> 3.5695 | X8: =W8/$W$48 -> 0.0045912336 | Y8: =X8*$N$5 -> 0.11107747 | Z8: =Y8/T8 -> 0.022215493 | AF8: 5 | AG8: 0 | AH8: =AG8*AF8 -> 0 | AI8: =AH8/$AH$54 -> 0 | AJ8: =AI8*$O$5 -> 0 | AK8: =AJ8/AF8 -> 0
B9: 7 | C9: Toluene | E9: 0 | G9: =+E9/B9 -> 0 | H9: Aromatic | I9: 2 | J9: =+E9*$L$24 -> 0 | R9: Cyclopentane | S9: 0.2986 | T9: 5 | U9: Naphthene | V9: 8 | W9: =S9*T9 -> 1.493 | X9: =W9/$W$48 -> 0.0019203563 | Y9: =X9*$N$5 -> 0.046459913 | Z9: =Y9/T9 -> 0.0092919826 | AF9: 6 | AG9: 0 | AH9: =AG9*AF9 -> 0 | AI9: =AH9/$AH$54 -> 0 | AJ9: =AI9*$O$5 -> 0 | AK9: =AJ9/AF9 -> 0
B10: 9 | C10: Nonene | E10: 0.002798767 | G10: =+E10/B10 -> 0.00031097411 | H10: Aromatic | I10: 3 | J10: =+E10*$L$24 -> 0.0025690157 | L10: =+L3/D5 -> 0.18355471 | R10: 3-Methylpentane | S10: 9.5949 | T10: 6 | U10: iso-paraffin | V10: 9 | W10: =S10*T10 -> 57.5694 | X10: =W10/$W$48 -> 0.074048063 | Y10: =X10*$N$5 -> 1.7914731 | Z10: =Y10/T10 -> 0.29857885 | AF10: 7 | AG10: 0 | AH10: =AG10*AF10 -> 0 | AI10: =AH10/$AH$54 -> 0 | AJ10: =AI10*$O$5 -> 0 | AK10: =AJ10/AF10 -> 0
B11: 8 | C11: p-Xilene | E11: 0 | G11: =+E11/B11 -> 0 | H11: Aromatic | I11: 4 | J11: =+E11*$L$24 -> 0 | R11: 1t,4-Hexadiene | S11: 3.8919 | T11: 6 | U11: Olefin | V11: 10 | W11: =S11*T11 -> 23.3514 | X11: =W11/$W$48 -> 0.030035504 | Y11: =X11*$N$5 -> 0.72666042 | Z11: =Y11/T11 -> 0.12111007 | AF11: 8 | AG11: 2.5 | AH11: =AG11*AF11 -> 20 | AI11: =AH11/$AH$54 -> 0.013580498 | AJ11: =AI11*$O$5 -> 0.19214569 | AK11: =AJ11/AF11 -> 0.024018212
B12: 8 | C12: m-Xilene | E12: 0.28316949 | G12: =+E12/B12 -> 0.035396186 | H12: Aromatic | I12: 5 | J12: =+E12*$L$24 -> 0.25992404 | R12: Cyclohexane | S12: 0.9641 | T12: 6 | U12: Naphthene | V12: 11 | W12: =S12*T12 -> 5.7846 | X12: =W12/$W$48 -> 0.0074403837 | Y12: =X12*$N$5 -> 0.18000805 | Z12: =Y12/T12 -> 0.030001341 | AF12: 9 | AG12: 3.1 | AH12: =AG12*AF12 -> 27.9 | AI12: =AH12/$AH$54 -> 0.018944795 | AJ12: =AI12*$O$5 -> 0.26804324 | AK12: =AJ12/AF12 -> 0.029782582
B13: 8 | C13: Etilbenzene | E13: 0 | G13: =+E13/B13 -> 0 | H13: Aromatic | I13: 6 | J13: =+E13*$L$24 -> 0 | R13: n-Hexane | S13: 0.109 | T13: 6 | U13: paraffin | V13: 12 | W13: =S13*T13 -> 0.654 | X13: =W13/$W$48 -> 0.00084120094 | Y13: =X13*$N$5 -> 0.020351496 | Z13: =Y13/T13 -> 0.0033919159 | AF13: 10 | AG13: 7.9 | AH13: =AG13*AF13 -> 79 | AI13: =AH13/$AH$54 -> 0.053642969 | AJ13: =AI13*$O$5 -> 0.75897549 | AK13: =AJ13/AF13 -> 0.075897549
B14: 8 | C14: o-Xilene | E14: 0 | G14: =+E14/B14 -> 0 | H14: Aromatic | I14: 7 | J14: =+E14*$L$24 -> 0 | R14: Benzene | S14: 0.08 | T14: 6 | U14: Aromatic | V14: 13 | W14: =S14*T14 -> 0.48 | X14: =W14/$W$48 -> 0.00061739519 | Y14: =X14*$N$5 -> 0.014936878 | Z14: =Y14/T14 -> 0.0024894796 | AF14: 11 | AG14: 9.1 | AH14: =AG14*AF14 -> 100.1 | AI14: =AH14/$AH$54 -> 0.067970395 | AJ14: =AI14*$O$5 -> 0.9616892 | AK14: =AJ14/AF14 -> 0.087426291
B15: 9 | C15: Trimetilbenzene | E15: 0 | G15: =+E15/B15 -> 0 | H15: Aromatic | I15: 8 | J15: =+E15*$L$24 -> 0 | R15: 3-Ethylpentane | S15: 8.1824 | T15: 7 | U15: iso-paraffin | V15: 14 | W15: =S15*T15 -> 57.2768 | X15: =W15/$W$48 -> 0.07367171 | Y15: =X15*$N$5 -> 1.7823678 | Z15: =Y15/T15 -> 0.25462397 | AF15: 12 | AG15: 10.5 | AH15: =AG15*AF15 -> 126 | AI15: =AH15/$AH$54 -> 0.08555714 | AJ15: =AI15*$O$5 -> 1.2105179 | AK15: =AJ15/AF15 -> 0.10087649
B16: 10 | C16: Decene | E16: 0 | G16: =+E16/B16 -> 0 | H16: Olefin | I16: 9 | J16: =+E16*$L$24 -> 0 | R16: 2,4-Dimethylpentene-1 | S16: 5.7111 | T16: 7 | U16: Olefin | V16: 15 | W16: =S16*T16 -> 39.9777 | X16: =W16/$W$48 -> 0.051420916 | Y16: =X16*$N$5 -> 1.2440459 | Z16: =Y16/T16 -> 0.17772084 | AF16: 13 | AG16: 10.9 | AH16: =AG16*AF16 -> 141.7 | AI16: =AH16/$AH$54 -> 0.096217831 | AJ16: =AI16*$O$5 -> 1.3613522 | AK16: =AJ16/AF16 -> 0.1047194
B17: 10 | C17: Decano | E17: 0.02034641 | G17: =+E17/B17 -> 0.002034641 | H17: paraffin | I17: 10 | J17: =+E17*$L$24 -> 0.018676169 | R17: 1c,3-Dimethylcyclopentane | S17: 0.8706 | T17: 7 | U17: Naphthene | V17: 16 | W17: =S17*T17 -> 6.0942 | X17: =W17/$W$48 -> 0.0078386036 | Y17: =X17*$N$5 -> 0.18964233 | Z17: =Y17/T17 -> 0.027091762 | AF17: 14 | AG17: 10.7 | AH17: =AG17*AF17 -> 149.8 | AI17: =AH17/$AH$54 -> 0.10171793 | AJ17: =AI17*$O$5 -> 1.4391712 | AK17: =AJ17/AF17 -> 0.10279795
B18: 1 | C18: *CH4 | E18: 12.780415 | G18: =+E18/B18 -> 12.780415 | H18: paraffin | I18: 11 | J18: =+E18*$L$24 -> 11.731268 | R18: Toluene | S18: 0.2139 | T18: 7 | U18: Aromatic | V18: 17 | W18: =S18*T18 -> 1.4973 | X18: =W18/$W$48 -> 0.0019258871 | Y18: =X18*$N$5 -> 0.046593722 | Z18: =Y18/T18 -> 0.006656246 | AF18: 15 | AG18: 9.5 | AH18: =AG18*AF18 -> 142.5 | AI18: =AH18/$AH$54 -> 0.096761051 | AJ18: =AI18*$O$5 -> 1.3690381 | AK18: =AJ18/AF18 -> 0.091269204
B19: 2 | C19: *Etilene | E19: 7.466552 | G19: =+E19/B19 -> 3.733276 | H19: Olefin | I19: 12 | J19: =+E19*$L$24 -> 6.8536212 | R19: Octene-1 | S19: 9.3793 | T19: 8 | U19: Olefin | V19: 18 | W19: =S19*T19 -> 75.0344 | X19: =W19/$W$48 -> 0.096512245 | Y19: =X19*$N$5 -> 2.3349576 | Z19: =Y19/T19 -> 0.2918697 | AF19: 16 | AG19: 7.7 | AH19: =AG19*AF19 -> 123.2 | AI19: =AH19/$AH$54 -> 0.08365587 | AJ19: =AI19*$O$5 -> 1.1836175 | AK19: =AJ19/AF19 -> 0.073976092
B20: 2 | C20: *Acetilene | E20: 0 | G20: =+E20/B20 -> 0 | H20: Olefin | I20: 13 | J20: =+E20*$L$24 -> 0 | R20: Ethylbenzene | S20: 1.767 | T20: 8 | U20: Aromatic | V20: 19 | W20: =S20*T20 -> 14.136 | X20: =W20/$W$48 -> 0.018182288 | Y20: =X20*$N$5 -> 0.43989104 | Z20: =Y20/T20 -> 0.05498638 | AF20: 17 | AG20: 6.7 | AH20: =AG20*AF20 -> 113.9 | AI20: =AH20/$AH$54 -> 0.077340938 | AJ20: =AI20*$O$5 -> 1.0942697 | AK20: =AJ20/AF20 -> 0.064368807
B21: 2 | C21: *Etano | E21: 1.7028996 | G21: =+E21/B21 -> 0.85144979 | H21: paraffin | I21: 14 | J21: =+E21*$L$24 -> 1.5631082 | R21: 2-Methyl-3-ethylpentane | S21: 3.4165 | T21: 8 | U21: iso-paraffin | V21: 20 | W21: =S21*T21 -> 27.332 | X21: =W21/$W$48 -> 0.035155511 | Y21: =X21*$N$5 -> 0.8505307 | Z21: =Y21/T21 -> 0.10631634 | AF21: 18 | AG21: 6.2 | AH21: =AG21*AF21 -> 111.6 | AI21: =AH21/$AH$54 -> 0.075779181 | AJ21: =AI21*$O$5 -> 1.072173 | AK21: =AJ21/AF21 -> 0.059565165
B22: 3 | C22: *Propilene | E22: 11.160259 | G22: =+E22/B22 -> 3.7200863 | H22: Olefin | I22: 15 | J22: =+E22*$L$24 -> 10.244111 | R22: 1c,2t,3-Trimethylcyclopentane | S22: 1.5336 | T22: 8 | U22: Naphthene | V22: 21 | W22: =S22*T22 -> 12.2688 | X22: =W22/$W$48 -> 0.015780621 | Y22: =X22*$N$5 -> 0.38178659 | Z22: =Y22/T22 -> 0.047723324 | AF22: 19 | AG22: 2.8 | AH22: =AG22*AF22 -> 53.2 | AI22: =AH22/$AH$54 -> 0.036124126 | AJ22: =AI22*$O$5 -> 0.51110754 | AK22: =AJ22/AF22 -> 0.026900397
B23: 3 | C23: *Propano | E23: 1.10465 | G23: =+E23/B23 -> 0.36821667 | H23: paraffin | I23: 16 | J23: =+E23*$L$24 -> 1.0139691 | R23: n-Octane | S23: 0.0333 | T23: 8 | U23: paraffin | V23: 22 | W23: =S23*T23 -> 0.2664 | X23: =W23/$W$48 -> 0.00034265433 | Y23: =X23*$N$5 -> 0.008289967 | Z23: =Y23/T23 -> 0.0010362459 | AF23: 20 | AG23: 2.2 | AH23: =AG23*AF23 -> 44 | AI23: =AH23/$AH$54 -> 0.029877096 | AJ23: =AI23*$O$5 -> 0.42272053 | AK23: =AJ23/AF23 -> 0.021136026
B24: 2 | C24: *DME | E24: 0.0027567702 | G24: =+E24/B24 -> 0.0013783851 | H24: oxygenated | I24: 17 | J24: =+E24*$L$24 -> 0.0025304663 | L24: =+(E5-14)/E5 -> 0.91790979 | R24: I8 (C9) | S24: 8.9828 | T24: 9 | U24: iso-paraffin | V24: 23 | W24: =S24*T24 -> 80.8452 | X24: =W24/$W$48 -> 0.10398633 | Y24: =X24*$N$5 -> 2.5157809 | Z24: =Y24/T24 -> 0.27953122 | AF24: 21 | AG24: 2 | AH24: =AG24*AF24 -> 42 | AI24: =AH24/$AH$54 -> 0.028519047 | AJ24: =AI24*$O$5 -> 0.40350596 | AK24: =AJ24/AF24 -> 0.019214569
B25: 1 | C25: Metanolo | E25: 0.93023541 | G25: =+E25/B25 -> 0.93023541 | H25: oxygenated | I25: 18 | J25: =+E25*$L$24 -> 0.85387219 | R25: 3,5,5-Trimethylhexene-1 | S25: 1.6554 | T25: 9 | U25: Olefin | V25: 24 | W25: =S25*T25 -> 14.8986 | X25: =W25/$W$48 -> 0.019163175 | Y25: =X25*$N$5 -> 0.46362201 | Z25: =Y25/T25 -> 0.051513556 | AF25: 22 | AG25: 1.8 | AH25: =AG25*AF25 -> 39.6 | AI25: =AH25/$AH$54 -> 0.026889387 | AJ25: =AI25*$O$5 -> 0.38044847 | AK25: =AJ25/AF25 -> 0.017293112
B26: 4 | C26: 2-Metilpropene | E26: 0.1091762 | G26: =+E26/B26 -> 0.027294049 | H26: Olefin | I26: 19 | J26: =+E26*$L$24 -> 0.1002139 | R26: 1,3-Methylethylbenzene | S26: 2.332 | T26: 9 | U26: Aromatic | V26: 25 | W26: =S26*T26 -> 20.988 | X26: =W26/$W$48 -> 0.026995605 | Y26: =X26*$N$5 -> 0.65311497 | Z26: =Y26/T26 -> 0.07256833 | AF26: 23 | AG26: 1.6 | AH26: =AG26*AF26 -> 36.8 | AI26: =AH26/$AH$54 -> 0.024988117 | AJ26: =AI26*$O$5 -> 0.35354808 | AK26: =AJ26/AF26 -> 0.015371655
B27: 4 | C27: *1-Butene | E27: 8.0319531 | G27: =+E27/B27 -> 2.0079883 | H27: Olefin | I27: 20 | J27: =+E27*$L$24 -> 7.3726084 | R27: n-Nonane | S27: 0.7169 | T27: 9 | U27: paraffin | V27: 26 | W27: =S27*T27 -> 6.4521 | X27: =W27/$W$48 -> 0.0082989489 | Y27: =X27*$N$5 -> 0.20077964 | Z27: =Y27/T27 -> 0.022308849 | AF27: 24 | AG27: 1.5 | AH27: =AG27*AF27 -> 36 | AI27: =AH27/$AH$54 -> 0.024444897 | AJ27: =AI27*$O$5 -> 0.34586225 | AK27: =AJ27/AF27 -> 0.014410927
B28: 4 | C28: *N-Butano | E28: 1.0696398 | G28: =+E28/B28 -> 0.26740996 | H28: paraffin | I28: 21 | J28: =+E28*$L$24 -> 0.98183288 | R28: 1,1,3-Trimethylcyclohexane | S28: 0.9332 | T28: 9 | U28: Naphthene | V28: 27 | W28: =S28*T28 -> 8.3988 | X28: =W28/$W$48 -> 0.010802872 | Y28: =X28*$N$5 -> 0.26135801 | Z28: =Y28/T28 -> 0.029039779 | AF28: 25 | AG28: 1.3 | AH28: =AG28*AF28 -> 32.5 | AI28: =AH28/$AH$54 -> 0.02206831 | AJ28: =AI28*$O$5 -> 0.31223675 | AK28: =AJ28/AF28 -> 0.01248947
B29: 4 | C29: 2-Butene | E29: 0.14396901 | G29: =+E29/B29 -> 0.035992252 | H29: Olefin | I29: 22 | J29: =+E29*$L$24 -> 0.13215056 | R29: Decene-1 | S29: 3.3315 | T29: 10 | U29: Olefin | V29: 28 | W29: =S29*T29 -> 33.315 | X29: =W29/$W$48 -> 0.042851085 | Y29: =X29*$N$5 -> 1.0367127 | Z29: =Y29/T29 -> 0.10367127 | AF29: 26 | AG29: 1.1 | AH29: =AG29*AF29 -> 28.6 | AI29: =AH29/$AH$54 -> 0.019420113 | AJ29: =AI29*$O$5 -> 0.27476834 | AK29: =AJ29/AF29 -> 0.010568013
B30: 5 | C30: 3-Metilbut-1-ene | E30: 0.089726599 | G30: =+E30/B30 -> 0.01794532 | H30: Olefin | I30: 23 | J30: =+E30*$L$24 -> 0.082360924 | R30: I15 (C10) | S30: 3.0536 | T30: 10 | U30: iso-paraffin | V30: 29 | W30: =S30*T30 -> 30.536 | X30: =W30/$W$48 -> 0.039276624 | Y30: =X30*$N$5 -> 0.95023436 | Z30: =Y30/T30 -> 0.095023436 | AF30: 27 | AG30: 0.9 | AH30: =AG30*AF30 -> 24.3 | AI30: =AH30/$AH$54 -> 0.016500306 | AJ30: =AI30*$O$5 -> 0.23345702 | AK30: =AJ30/AF30 -> 0.0086465562
B31: 5 | C31: 2-Metilbutano | E31: 0.32813986 | G31: =+E31/B31 -> 0.065627973 | H31: iso-paraffin | I31: 24 | J31: =+E31*$L$24 -> 0.30120279 | R31: 1,2-Methyl-n-propylbenzene | S31: 2.3726 | T31: 10 | U31: Aromatic | V31: 30 | W31: =S31*T31 -> 23.726 | X31: =W31/$W$48 -> 0.03051733 | Y31: =X31*$N$5 -> 0.73831741 | Z31: =Y31/T31 -> 0.073831741 | AF31: 28 | AG31: 0 | AH31: =AG31*AF31 -> 0 | AI31: =AH31/$AH$54 -> 0 | AJ31: =AI31*$O$5 -> 0 | AK31: =AJ31/AF31 -> 0
B32: 5 | C32: 2-Metilbut-1-ene | E32: 0.7360527 | G32: =+E32/B32 -> 0.14721054 | H32: Olefin | I32: 25 | J32: =+E32*$L$24 -> 0.67562998 | R32: Sec-butylcyclohexane | S32: 1.9382 | T32: 10 | U32: Naphthene | V32: 31 | W32: =S32*T32 -> 19.382 | X32: =W32/$W$48 -> 0.024929903 | Y32: =X32*$N$5 -> 0.60313867 | Z32: =Y32/T32 -> 0.060313867 | AF32: 29 | AG32: 0 | AH32: =AG32*AF32 -> 0 | AI32: =AH32/$AH$54 -> 0 | AJ32: =AI32*$O$5 -> 0 | AK32: =AJ32/AF32 -> 0
B33: 5 | C33: *1-Pentene | E33: 4.915713 | G33: =+E33/B33 -> 0.98314259 | H33: Olefin | I33: 26 | J33: =+E33*$L$24 -> 4.512181 | R33: Undecene-1 | S33: 2.0365 | T33: 11 | U33: Olefin | V33: 32 | W33: =S33*T33 -> 22.4015 | X33: =W33/$W$48 -> 0.028813705 | Y33: =X33*$N$5 -> 0.69710096 | Z33: =Y33/T33 -> 0.063372815 | AF33: 30 | AG33: 0 | AH33: =AG33*AF33 -> 0 | AI33: =AH33/$AH$54 -> 0 | AJ33: =AI33*$O$5 -> 0 | AK33: =AJ33/AF33 -> 0
B34: 5 | C34: 2-Pentene | E34: 0.076394073 | G34: =+E34/B34 -> 0.015278815 | H34: Olefin | I34: 27 | J34: =+E34*$L$24 -> 0.070122868 | R34: I26 (C11) | S34: 3.1631 | T34: 11 | U34: iso-paraffin | V34: 33 | W34: =S34*T34 -> 34.7941 | X34: =W34/$W$48 -> 0.044753562 | Y34: =X34*$N$5 -> 1.08274 | Z34: =Y34/T34 -> 0.098430911 | AF34: 31 | AG34: 0 | AH34: =AG34*AF34 -> 0 | AI34: =AH34/$AH$54 -> 0 | AJ34: =AI34*$O$5 -> 0 | AK34: =AJ34/AF34 -> 0
B35: 5 | C35: *Pentano | E35: 0 | G35: =+E35/B35 -> 0 | H35: paraffin | I35: 28 | J35: =+E35*$L$24 -> 0 | R35: 1,2-Ethyl-i-propylbenzene | S35: 1.2679 | T35: 11 | U35: Aromatic | V35: 34 | W35: =S35*T35 -> 13.9469 | X35: =W35/$W$48 -> 0.01793906 | Y35: =X35*$N$5 -> 0.43400654 | Z35: =Y35/T35 -> 0.03945514 | AF35: 32 | AG35: 0 | AH35: =AG35*AF35 -> 0 | AI35: =AH35/$AH$54 -> 0 | AJ35: =AI35*$O$5 -> 0 | AK35: =AJ35/AF35 -> 0
B36: 6 | C36: 2-Metilbut-2-ene | E36: 0.0064126282 | G36: =+E36/B36 -> 0.0010687714 | H36: Olefin | I36: 29 | J36: =+E36*$L$24 -> 0.0058862142 | R36: n-Undecane | S36: 0.0822 | T36: 11 | U36: paraffin | V36: 35 | W36: =S36*T36 -> 0.9042 | X36: =W36/$W$48 -> 0.0011630182 | Y36: =X36*$N$5 -> 0.028137343 | Z36: =Y36/T36 -> 0.0025579403 | AF36: 33 | AG36: 0 | AH36: =AG36*AF36 -> 0 | AI36: =AH36/$AH$54 -> 0 | AJ36: =AI36*$O$5 -> 0 | AK36: =AJ36/AF36 -> 0
... B43: 7 | C43: 2,2-Dimetilpentano | E43: 0.0038738257 | G43: =+E43/B43 -> 0.00055340367 | H43: iso-paraffin | I43: 36 | J43: =+E43*$L$24 -> 0.0035558225 | R43: (C14-IsoParaffin) | S43: 0.1832 | T43: 14 | U43: iso-paraffin | V43: 42 | W43: =S43*T43 -> 2.5648 | X43: =W43/$W$48 -> 0.0032989483 | Y43: =X43*$N$5 -> 0.079812716 | Z43: =Y43/T43 -> 0.0057009083 | AF43: 40 | AG43: 0 | AH43: =AG43*AF43 -> 0 | AI43: =AH43/$AH$54 -> 0 | AJ43: =AI43*$O$5 -> 0 | AK43: =AJ43/AF43 -> 0
B44: 7 | C44: 2-Metiles-1-ene | E44: 0.00035118397 | G44: =+E44/B44 -> 5.0169138e-05 | H44: Olefin | I44: 37 | J44: =+E44*$L$24 -> 0.0003223552 | R44: (C15-IsoParaffin) | S44: 0.1445 | T44: 15 | U44: iso-paraffin | V44: 43 | W44: =S44*T44 -> 2.1675 | X44: =W44/$W$48 -> 0.0027879251 | Y44: =X44*$N$5 -> 0.067449338 | Z44: =Y44/T44 -> 0.0044966225 | AF44: 48 | AH44: =AG44*AF44 -> 0 | AI44: =AH44/$AH$54 -> 0 | AJ44: =AI44*$O$5 -> 0 | AK44: =AJ44/AF44 -> 0
B45: 7 | C45: 1-eptene | E45: 0.0037203478 | G45: =+E45/B45 -> 0.00053147826 | H45: Olefin | I45: 38 | J45: =+E45*$L$24 -> 0.0034149437 | R45: (C16-IsoParaffin) | S45: 0.3685 | T45: 16 | U45: iso-paraffin | V45: 44 | W45: =S45*T45 -> 5.896 | X45: =W45/$W$48 -> 0.0075836709 | Y45: =X45*$N$5 -> 0.18347465 | Z45: =Y45/T45 -> 0.011467165 | AF45: 49 | AH45: =AG45*AF45 -> 0 | AI45: =AH45/$AH$54 -> 0 | AJ45: =AI45*$O$5 -> 0 | AK45: =AJ45/AF45 -> 0
B46: 7 | C46: Eptano | E46: 0.0001074849 | G46: =+E46/B46 -> 1.5354985e-05 | H46: paraffin | I46: 39 | J46: =+E46*$L$24 -> 9.866144e-05 | R46: (C17-IsoParaffin) | S46: 0.1365 | T46: 17 | U46: iso-paraffin | V46: 45 | W46: =S46*T46 -> 2.3205 | X46: =W46/$W$48 -> 0.0029847199 | Y46: =X46*$N$5 -> 0.072210467 | Z46: =Y46/T46 -> 0.0042476745 | AF46: 50 | AH46: =AG46*AF46 -> 0 | AI46: =AH46/$AH$54 -> 0 | AJ46: =AI46*$O$5 -> 0 | AK46: =AJ46/AF46 -> 0
...

Sheet 10% CO Elab
Y2: TOT CO | Z2: TOT CO2 | AA2: TOT CO IN | AB2: TOT CO2 IN
B3: Cn | C3: Class | D3: Name | E3: mol | F3: Colonna1 | G3: Colonna2 | Y3: ='10% CO'!D6-'10% CO'!E6 -> 75.609208 | Z3: =+'10% CO'!D7-'10% CO'!E7 -> 17.105493 | AA3: =+'10% CO'!D6 -> 84.481827 | AB3: =+'10% CO'!D7 -> 124.40429
B4: ='5% CO'!B8 -> 8 | C4: ='5% CO'!H8 -> Olefin | D4: ='5% CO'!C8 -> Ottene | E4: =+'10% CO'!G8 -> 0 | F4: 1-GAS | G4: =VLOOKUP(Tabella10[[#This Row],[Name]],'10% CO'!$C$8:$I$47,7,FALSE) -> 1 | Y4: =Y3/(Y3+Z3) -> 0.81550398 | Z4: =1-Y4 -> 0.18449602
B5: ='5% CO'!B9 -> 7 | C5: ='5% CO'!H9 -> Aromatic | D5: ='5% CO'!C9 -> Toluene | E5: =+'10% CO'!G9 -> 0 | F5: 1-GAS | G5: =VLOOKUP(Tabella10[[#This Row],[Name]],'10% CO'!$C$8:$I$47,7,FALSE) -> 2 | R5: Colonna1 | S5: Colonna2 | T5: Colonna3 | U5: Colonna4 | V5: Colonna5 | W5: mmol | X5: mmolC | Y5: Colonna6 | Z5: Colonna7 | AA5: con CO | AB5: conv CO2
B6: ='5% CO'!B10 -> 9 | C6: ='5% CO'!H10 -> Aromatic | D6: ='5% CO'!C10 -> Nonene | E6: =+'10% CO'!G10 -> 0.00031097411 | F6: 1-GAS | G6: =VLOOKUP(Tabella10[[#This Row],[Name]],'10% CO'!$C$8:$I$47,7,FALSE) -> 3 | R6: 1 | S6: 1 | T6: METHANE | U6: CH4 | V6: CH4 | W6: =GETPIVOTDATA("mol",$N$17,"Cn",1,"Class","paraffin") -> 12.780415 | X6: =+W6*S6 -> 12.780415 | Y6: =X6*$Y$4 -> 10.422479 | Z6: =+X6*$Z$4 -> 2.3579357 | AA6: =+Y6/$AA$3 -> 0.12336948 | AB6: =+Z6/$AB$3 -> 0.018953813
B7: ='5% CO'!B11 -> 8 | C7: ='5% CO'!H11 -> Aromatic | D7: ='5% CO'!C11 -> p-Xilene | E7: =+'10% CO'!G11 -> 0 | F7: 1-GAS | G7: =VLOOKUP(Tabella10[[#This Row],[Name]],'10% CO'!$C$8:$I$47,7,FALSE) -> 4 | R7: 2 | S7: 1 | T7: METHANOL | U7: CH4O | V7: MEOH | W7: =+GETPIVOTDATA("mol",$N$17,"Cn",1,"Class","oxygenated") -> 0.93023541 | X7: =+W7*S7 -> 0.93023541 | Y7: =X7*$Y$4 -> 0.75861068 | Z7: =+X7*$Z$4 -> 0.17162473 | AA7: =+Y7/$AA$3 -> 0.0089795723 | AB7: =+Z7/$AB$3 -> 0.0013795724 | AH7: Etichette di riga | AI7: Somma di mmolC
B8: ='5% CO'!B12 -> 8 | C8: ='5% CO'!H12 -> Aromatic | D8: ='5% CO'!C12 -> m-Xilene | E8: =+'10% CO'!G12 -> 0.035396186 | F8: 1-GAS | G8: =VLOOKUP(Tabella10[[#This Row],[Name]],'10% CO'!$C$8:$I$47,7,FALSE) -> 5 | R8: 3 | S8: 2 | T8: ETHANE | U8: C2H6 | V8: C2 | W8: =+GETPIVOTDATA("mol",$N$17,"Cn",2,"Class","paraffin") -> 0.85144979 | X8: =+W8*S8 -> 1.7028996 | Y8: =X8*$Y$4 -> 1.3887214 | Z8: =+X8*$Z$4 -> 0.31417819 | AA8: =+Y8/$AA$3 -> 0.016438108 | AB8: =+Z8/$AB$3 -> 0.002525461 | AH8: 1 | AI8: 13.71065
B9: ='5% CO'!B13 -> 8 | C9: ='5% CO'!H13 -> Aromatic | D9: ='5% CO'!C13 -> Etilbenzene | E9: =+'10% CO'!G13 -> 0 | F9: 1-GAS | G9: =VLOOKUP(Tabella10[[#This Row],[Name]],'10% CO'!$C$8:$I$47,7,FALSE) -> 6 | R9: 4 | S9: 2 | T9: ETHYLENE | U9: C2H4 | V9: C2-O | W9: =+GETPIVOTDATA("mol",$N$17,"Cn",2,"Class","Olefin") -> 3.733276 | X9: =+W9*S9 -> 7.466552 | Y9: =X9*$Y$4 -> 6.0890029 | Z9: =+X9*$Z$4 -> 1.3775491 | AA9: =+Y9/$AA$3 -> 0.072074707 | AB9: =+Z9/$AB$3 -> 0.011073164 | AH9: 2 | AI9: 9.1694516
B10: ='5% CO'!B14 -> 8 | C10: ='5% CO'!H14 -> Aromatic | D10: ='5% CO'!C14 -> o-Xilene | E10: =+'10% CO'!G14 -> 0 | F10: 1-GAS | G10: =VLOOKUP(Tabella10[[#This Row],[Name]],'10% CO'!$C$8:$I$47,7,FALSE) -> 7 | R10: 5 | S10: 3 | T10: PROPANE | U10: C3H8 | V10: C3 | W10: =+GETPIVOTDATA("mol",$N$17,"Cn",3,"Class","paraffin") -> 0.39016144 | X10: =+W10*S10 -> 1.1704843 | Y10: =X10*$Y$4 -> 0.95453461 | Z10: =+X10*$Z$4 -> 0.21594969 | AA10: =+Y10/$AA$3 -> 0.011298698 | AB10: =+Z10/$AB$3 -> 0.0017358701 | AH10: 3 | AI10: 12.330743
B11: ='5% CO'!B15 -> 9 | C11: ='5% CO'!H15 -> Aromatic | D11: ='5% CO'!C15 -> Trimetilbenzene | E11: =+'10% CO'!G15 -> 0 | F11: 1-GAS | G11: =VLOOKUP(Tabella10[[#This Row],[Name]],'10% CO'!$C$8:$I$47,7,FALSE) -> 8 | R11: 6 | S11: 3 | T11: PROPYLENE | U11: C3H6-2 | V11: C3-O | W11: =+GETPIVOTDATA("mol",$N$17,"Cn",3,"Class","Olefin") -> 3.7200863 | X11: =+W11*S11 -> 11.160259 | Y11: =X11*$Y$4 -> 9.1012356 | Z11: =+X11*$Z$4 -> 2.0590233 | AA11: =+Y11/$AA$3 -> 0.1077301 | AB11: =+Z11/$AB$3 -> 0.016551063 | AH11: 4 | AI11: 9.9901903
B12: ='5% CO'!B16 -> 10 | C12: ='5% CO'!H16 -> Olefin | D12: ='5% CO'!C16 -> Decene | E12: =+'10% CO'!G16 -> 0 | F12: 1-GAS | G12: =VLOOKUP(Tabella10[[#This Row],[Name]],'10% CO'!$C$8:$I$47,7,FALSE) -> 9 | R12: 7 | S12: 4 | T12: N-BUTANE | U12: C4H10-1 | V12: C4 | W12: =+GETPIVOTDATA("mol",$N$17,"Cn",4,"Class","paraffin") -> 0.28059487 | X12: =+W12*S12 -> 1.1223795 | Y12: =X12*$Y$4 -> 0.91530493 | Z12: =+X12*$Z$4 -> 0.20707454 | AA12: =+Y12/$AA$3 -> 0.010834341 | AB12: =+Z12/$AB$3 -> 0.0016645289 | AH12: 5 | AI12: 7.9271088
B13: ='5% CO'!B17 -> 10 | C13: ='5% CO'!H17 -> paraffin | D13: ='5% CO'!C17 -> Decano | E13: =+'10% CO'!G17 -> 0.002034641 | F13: 1-GAS | G13: =VLOOKUP(Tabella10[[#This Row],[Name]],'10% CO'!$C$8:$I$47,7,FALSE) -> 10 | R13: 8 | S13: 4 | T13: ISOBUTANE | U13: C4H10-2 | V13: C4-IP | W13: =+GETPIVOTDATA("mol",$N$17,"Cn",4,"Class","iso-paraffin") -> 0.0076987156 | X13: =+W13*S13 -> 0.030794862 | Y13: =X13*$Y$4 -> 0.025113333 | Z13: =+X13*$Z$4 -> 0.0056815295 | AA13: =+Y13/$AA$3 -> 0.00029726314 | AB13: =+Z13/$AB$3 -> 4.5669883e-05 | AH13: 6 | AI13: 6.0726972
B14: ='5% CO'!B18 -> 1 | C14: ='5% CO'!H18 -> paraffin | D14: ='5% CO'!C18 -> *CH4 | E14: =+'10% CO'!G18 -> 12.780415 | F14: 1-GAS | G14: =VLOOKUP(Tabella10[[#This Row],[Name]],'10% CO'!$C$8:$I$47,7,FALSE) -> 11 | R14: 9 | S14: 4 | T14: 1-BUTENE | U14: C4H8-1 | V14: C4-O | W14: =+GETPIVOTDATA("mol",$N$17,"Cn",4,"Class","Olefin") -> 2.209254 | X14: =+W14*S14 -> 8.837016 | Y14: =X14*$Y$4 -> 7.2066217 | Z14: =+X14*$Z$4 -> 1.6303942 | AA14: =+Y14/$AA$3 -> 0.08530381 | AB14: =+Z14/$AB$3 -> 0.013105611 | AH14: 7 | AI14: 3.3412065
B15: ='5% CO'!B19 -> 2 | C15: ='5% CO'!H19 -> Olefin | D15: ='5% CO'!C19 -> *Etilene | E15: =+'10% CO'!G19 -> 3.733276 | F15: 1-GAS | G15: =VLOOKUP(Tabella10[[#This Row],[Name]],'10% CO'!$C$8:$I$47,7,FALSE) -> 12 | R15: 10 | S15: 5 | T15: N-PENTANE | U15: C5H12-1 | V15: C5 | W15: =+GETPIVOTDATA("mol",$N$17,"Cn",5,"Class","paraffin") -> 0.026257786 | X15: =+W15*S15 -> 0.13128893 | Y15: =X15*$Y$4 -> 0.10706665 | Z15: =+X15*$Z$4 -> 0.024222285 | AA15: =+Y15/$AA$3 -> 0.0012673334 | AB15: =+Z15/$AB$3 -> 0.00019470618 | AH15: 8 | AI15: 4.4907711
B16: ='5% CO'!B20 -> 2 | C16: ='5% CO'!H20 -> Olefin | D16: ='5% CO'!C20 -> *Acetilene | E16: =+'10% CO'!G20 -> 0 | F16: 1-GAS | G16: =VLOOKUP(Tabella10[[#This Row],[Name]],'10% CO'!$C$8:$I$47,7,FALSE) -> 13 | R16: 11 | S16: 5 | T16: 2-METHYL-1-BUTANE | U16: C5H12-5 | V16: C5-IP | W16: =+GETPIVOTDATA("mol",$N$17,"Cn",5,"Class","iso-paraffin") -> 0.087843466 | X16: =+W16*S16 -> 0.43921733 | Y16: =X16*$Y$4 -> 0.35818348 | Z16: =+X16*$Z$4 -> 0.081033848 | AA16: =+Y16/$AA$3 -> 0.0042397696 | AB16: =+Z16/$AB$3 -> 0.00065137502 | AH16: 9 | AI16: 4.3654976
B17: ='5% CO'!B21 -> 2 | C17: ='5% CO'!H21 -> paraffin | D17: ='5% CO'!C21 -> *Etano | E17: =+'10% CO'!G21 -> 0.85144979 | F17: 1-GAS | G17: =VLOOKUP(Tabella10[[#This Row],[Name]],'10% CO'!$C$8:$I$47,7,FALSE) -> 14 | N17: Cn | O17: Class | P17: Somma di mol | R17: 12 | S17: 5 | T17: 1-PENTENE | U17: C5H10-2 | V17: C5-O | W17: =+GETPIVOTDATA("mol",$N$17,"Cn",5,"Class","Olefin") -> 1.4620285 | X17: =+W17*S17 -> 7.3101426 | Y17: =X17*$Y$4 -> 5.9614504 | Z17: =+X17*$Z$4 -> 1.3486922 | AA17: =+Y17/$AA$3 -> 0.070564885 | AB17: =+Z17/$AB$3 -> 0.010841203 | AH17: 10 | AI17: 4.107725
B18: ='5% CO'!B22 -> 3 | C18: ='5% CO'!H22 -> Olefin | D18: ='5% CO'!C22 -> *Propilene | E18: =+'10% CO'!G22 -> 3.7200863 | F18: 1-GAS | G18: =VLOOKUP(Tabella10[[#This Row],[Name]],'10% CO'!$C$8:$I$47,7,FALSE) -> 15 | N18: 1 | O18: oxygenated | P18: 0.93023541 | R18: 13 | S18: 5 | T18: CYCLOPENTANE | V18: C5-N | W18: =+GETPIVOTDATA("mol",$N$17,"Cn",5,"Class","Naphthene") -> 0.0092919826 | X18: =+W18*S18 -> 0.046459913 | Y18: =X18*$Y$4 -> 0.037888244 | Z18: =+X18*$Z$4 -> 0.0085716688 | AA18: =+Y18/$AA$3 -> 0.00044847804 | AB18: =+Z18/$AB$3 -> 6.8901714e-05 | AH18: 11 | AI18: 3.2036741
B19: ='5% CO'!B23 -> 3 | C19: ='5% CO'!H23 -> paraffin | D19: ='5% CO'!C23 -> *Propano | E19: =+'10% CO'!G23 -> 0.36821667 | F19: 1-GAS | G19: =VLOOKUP(Tabella10[[#This Row],[Name]],'10% CO'!$C$8:$I$47,7,FALSE) -> 16 | N19: 1 | O19: paraffin | P19: 12.780415 | R19: 14 | S19: 6 | T19: 2,2-DIMETHYL-BUTANE | U19: C6H14-4 | V19: C6-IP | W19: =+GETPIVOTDATA("mol",$N$17,"Cn",6,"Class","iso-paraffin") -> 0.34416377 | X19: =+W19*S19 -> 2.0649826 | Y19: =X19*$Y$4 -> 1.6840016 | Z19: =+X19*$Z$4 -> 0.38098107 | AA19: =+Y19/$AA$3 -> 0.019933299 | AB19: =+Z19/$AB$3 -> 0.0030624432 | AH19: 12 | AI19: 2.4880317
B20: ='5% CO'!B24 -> 2 | C20: ='5% CO'!H24 -> oxygenated | D20: ='5% CO'!C24 -> *DME | E20: =+'10% CO'!G24 -> 0.0013783851 | F20: 1-GAS | G20: =VLOOKUP(Tabella10[[#This Row],[Name]],'10% CO'!$C$8:$I$47,7,FALSE) -> 17 | N20: 2 | O20: Olefin | P20: 3.733276 | R20: 15 | S20: 6 | T20: N-HEXANE | U20: C6H14-1 | V20: C6 | W20: =+GETPIVOTDATA("mol",$N$17,"Cn",6,"Class","paraffin") -> 0.0049116408 | X20: =+W20*S20 -> 0.029469845 | Y20: =X20*$Y$4 -> 0.024032776 | Z20: =+X20*$Z$4 -> 0.0054370689 | AA20: =+Y20/$AA$3 -> 0.00028447273 | AB20: =+Z20/$AB$3 -> 4.3704834e-05 | AH20: 13 | AI20: 1.7153251
B21: ='5% CO'!B25 -> 1 | C21: ='5% CO'!H25 -> oxygenated | D21: ='5% CO'!C25 -> Metanolo | E21: =+'10% CO'!G25 -> 0.93023541 | F21: 1-GAS | G21: =VLOOKUP(Tabella10[[#This Row],[Name]],'10% CO'!$C$8:$I$47,7,FALSE) -> 18 | N21: 2 | O21: oxygenated | P21: 0.0013783851 | R21: 16 | S21: 6 | T21: 2-METHYL-1-PENTENE | U21: C6H12-D2 | V21: C6-O | W21: =+GETPIVOTDATA("mol",$N$17,"Cn",6,"Class","Olefin") -> 0.63054997 | X21: =+W21*S21 -> 3.7832998 | Y21: =X21*$Y$4 -> 3.0852961 | Z21: =+X21*$Z$4 -> 0.69800374 | AA21: =+Y21/$AA$3 -> 0.036520233 | AB21: =+Z21/$AB$3 -> 0.005610769 | AH21: 14 | AI21: 1.518984
B22: ='5% CO'!B26 -> 4 | C22: ='5% CO'!H26 -> Olefin | D22: ='5% CO'!C26 -> 2-Metilpropene | E22: =+'10% CO'!G26 -> 0.027294049 | F22: 1-GAS | G22: =VLOOKUP(Tabella10[[#This Row],[Name]],'10% CO'!$C$8:$I$47,7,FALSE) -> 19 | N22: 2 | O22: paraffin | P22: 0.85144979 | R22: 17 | S22: 6 | T22: BENZENE | V22: C6-A | W22: =+GETPIVOTDATA("mol",$N$17,"Cn",6,"Class","Aromatic") -> 0.0024894796 | X22: =+W22*S22 -> 0.014936878 | Y22: =X22*$Y$4 -> 0.012181083 | Z22: =+X22*$Z$4 -> 0.0027557944 | AA22: =+Y22/$AA$3 -> 0.00014418584 | AB22: =+Z22/$AB$3 -> 2.2151924e-05 | AH22: 15 | AI22: 1.4364874
B23: ='5% CO'!B27 -> 4 | C23: ='5% CO'!H27 -> Olefin | D23: ='5% CO'!C27 -> *1-Butene | E23: =+'10% CO'!G27 -> 2.0079883 | F23: 1-GAS | G23: =VLOOKUP(Tabella10[[#This Row],[Name]],'10% CO'!$C$8:$I$47,7,FALSE) -> 20 | N23: 3 | O23: Olefin | P23: 3.7200863 | R23: 18 | S23: 6 | T23: CYCLOHEXANE | V23: C6-N | W23: =+GETPIVOTDATA("mol",$N$17,"Cn",6,"Class","Naphthene") -> 0.030001341 | X23: =+W23*S23 -> 0.18000805 | Y23: =X23*$Y$4 -> 0.14679728 | Z23: =+X23*$Z$4 -> 0.033210767 | AA23: =+Y23/$AA$3 -> 0.0017376196 | AB23: =+Z23/$AB$3 -> 0.00026695837 | AH23: 16 | AI23: 1.3670921
B24: ='5% CO'!B28 -> 4 | C24: ='5% CO'!H28 -> paraffin | D24: ='5% CO'!C28 -> *N-Butano | E24: =+'10% CO'!G28 -> 0.26740996 | F24: 1-GAS | G24: =VLOOKUP(Tabella10[[#This Row],[Name]],'10% CO'!$C$8:$I$47,7,FALSE) -> 21 | N24: 3 | O24: paraffin | P24: 0.39016144 | R24: 19 | S24: 7 | T24: N-HEPTANE | U24: C7H16-1 | V24: C7 | W24: =+GETPIVOTDATA("mol",$N$17,"Cn",7,"Class","paraffin") -> 1.5354985e-05 | X24: =+W24*S24 -> 0.0001074849 | Y24: =X24*$Y$4 -> 8.7654363e-05 | Z24: =+X24*$Z$4 -> 1.9830536e-05 | AA24: =+Y24/$AA$3 -> 1.0375529e-06 | AB24: =+Z24/$AB$3 -> 1.5940395e-07 | AH24: 17 | AI24: 1.1664802
B25: ='5% CO'!B29 -> 4 | C25: ='5% CO'!H29 -> Olefin | D25: ='5% CO'!C29 -> 2-Butene | E25: =+'10% CO'!G29 -> 0.035992252 | F25: 1-GAS | G25: =VLOOKUP(Tabella10[[#This Row],[Name]],'10% CO'!$C$8:$I$47,7,FALSE) -> 22 | N25: 4 | O25: iso-paraffin | P25: 0.0076987156 | R25: 20 | S25: 7 | T25: 2-METHYLHEXANE | U25: C7H16-2 | V25: C7-IP | W25: =+GETPIVOTDATA("mol",$N$17,"Cn",7,"Class","iso-paraffin") -> 0.25517738 | X25: =+W25*S25 -> 1.7862416 | Y25: =X25*$Y$4 -> 1.4566872 | Z25: =+X25*$Z$4 -> 0.32955447 | AA25: =+Y25/$AA$3 -> 0.01724261 | AB25: =+Z25/$AB$3 -> 0.0026490603 | AH25: 18 | AI25: 1.072173
B26: ='5% CO'!B30 -> 5 | C26: ='5% CO'!H30 -> Olefin | D26: ='5% CO'!C30 -> 3-Metilbut-1-ene | E26: =+'10% CO'!G30 -> 0.01794532 | F26: 1-GAS | G26: =VLOOKUP(Tabella10[[#This Row],[Name]],'10% CO'!$C$8:$I$47,7,FALSE) -> 23 | N26: 4 | O26: Olefin | P26: 2.209254 | R26: 21 | S26: 7 | T26: 1-HEPTENE | U26: C7H14-7 | V26: C7-O | W26: =+GETPIVOTDATA("mol",$N$17,"Cn",7,"Class","Olefin") -> 0.18837448 | X26: =+W26*S26 -> 1.3186213 | Y26: =X26*$Y$4 -> 1.0753409 | Z26: =+X26*$Z$4 -> 0.24328038 | AA26: =+Y26/$AA$3 -> 0.012728666 | AB26: =+Z26/$AB$3 -> 0.0019555626 | AH26: 19 | AI26: 0.51110754
B27: ='5% CO'!B31 -> 5 | C27: ='5% CO'!H31 -> iso-paraffin | D27: ='5% CO'!C31 -> 2-Metilbutano | E27: =+'10% CO'!G31 -> 0.065627973 | F27: 1-GAS | G27: =VLOOKUP(Tabella10[[#This Row],[Name]],'10% CO'!$C$8:$I$47,7,FALSE) -> 24 | N27: 4 | O27: paraffin | P27: 0.28059487 | R27: 22 | S27: 7 | T27: TOLUENE | U27: C7H8 | V27: C7-A | W27: =+GETPIVOTDATA("mol",$N$17,"Cn",7,"Class","Aromatic") -> 0.006656246 | X27: =+W27*S27 -> 0.046593722 | Y27: =X27*$Y$4 -> 0.037997366 | Z27: =+X27*$Z$4 -> 0.0085963562 | AA27: =+Y27/$AA$3 -> 0.0004497697 | AB27: =+Z27/$AB$3 -> 6.9100158e-05 | AH27: 20 | AI27: 0.42272053
B28: ='5% CO'!B32 -> 5 | C28: ='5% CO'!H32 -> Olefin | D28: ='5% CO'!C32 -> 2-Metilbut-1-ene | E28: =+'10% CO'!G32 -> 0.14721054 | F28: 1-GAS | G28: =VLOOKUP(Tabella10[[#This Row],[Name]],'10% CO'!$C$8:$I$47,7,FALSE) -> 25 | N28: 5 | O28: iso-paraffin | P28: 0.087843466 | R28: 23 | S28: 7 | T28: 1c,3-Dimethylcyclopentane | V28: C7-N | W28: =+GETPIVOTDATA("mol",$N$17,"Cn",7,"Class","Naphthene") -> 0.027091762 | X28: =+W28*S28 -> 0.18964233 | Y28: =X28*$Y$4 -> 0.15465408 | Z28: =+X28*$Z$4 -> 0.034988255 | AA28: =+Y28/$AA$3 -> 0.0018306195 | AB28: =+Z28/$AB$3 -> 0.00028124637 | AH28: 21 | AI28: 0.40350596
