Workbook

Sheet Inlet
B2: CO2 | C2: kmol/hr | D2: 0.086674785 | F2: =+D2/SUM($D$2:$D$73) -> 0.013943353 | N2: 0.015209939
B3: H2O | C3: kmol/hr | D3: 0.0060443607 | F3: =+D3/SUM($D$2:$D$73) -> 0.00097235495 | N3: 0.0037286654
B4: H2 | C4: kmol/hr | D4: 5.8299315 | F4: =+D4/SUM($D$2:$D$73) -> 0.93785977 | N4: 5.9454045
B5: CO | C5: kmol/hr | D5: 4.8714785e-05 | F5: =+D5/SUM($D$2:$D$73) -> 7.8367365e-06 | N5: 2.1638773e-06
B6: CH4 | C6: kmol/hr | D6: 0.0007111447 | F6: =+D6/SUM($D$2:$D$73) -> 0.00011440169 | G6: =+D6/SUM($D$6:$D$73) -> 0.0024229081 | N6: 4.7211617e-05
B7: MEOH | C7: kmol/hr | D7: 0.0011591573 | F7: =+D7/SUM($D$2:$D$73) -> 0.00018647337 | G7: =+D7/SUM($D$6:$D$73) -> 0.003949311 | N7: 0.00067118241
B8: C2 | C8: kmol/hr | D8: 0.0025701201 | F8: =+D8/SUM($D$2:$D$73) -> 0.00041345464 | G8: =+D8/SUM($D$6:$D$73) -> 0.0087565369 | N8: 0.00052042266
B9: C2-O | C9: kmol/hr | D9: 0 | F9: =+D9/SUM($D$2:$D$73) -> 0 | G9: =+D9/SUM($D$6:$D$73) -> 0 | N9: 0
B10: C3 | C10: kmol/hr | D10: 0.02379387 | F10: =+D10/SUM($D$2:$D$73) -> 0.0038277146 | G10: =+D10/SUM($D$6:$D$73) -> 0.081066992 | N10: 0.0066226843
B11: C3-O | C11: kmol/hr | D11: 2.8280897e-09 | F11: =+D11/SUM($D$2:$D$73) -> 4.5495416e-10 | G11: =+D11/SUM($D$6:$D$73) -> 9.6354534e-09 | N11: 7.1638573e-10
B12: C4 | C12: kmol/hr | D12: 0.022656473 | F12: =+D12/SUM($D$2:$D$73) -> 0.0036447418 | G12: =+D12/SUM($D$6:$D$73) -> 0.07719182 | N12: 0.01036612
B13: C4-IP | C13: kmol/hr | D13: 6.568806e-05 | F13: =+D13/SUM($D$2:$D$73) -> 1.0567223e-05 | G13: =+D13/SUM($D$6:$D$73) -> 0.00022380274 | N13: 3.3472162e-05
B14: C4-O | C14: kmol/hr | D14: 8.1154749e-23 | F14: =+D14/SUM($D$2:$D$73) -> 1.3055346e-23 | G14: =+D14/SUM($D$6:$D$73) -> 2.7649858e-22 | N14: 3.9540472e-23
B15: C5 | C15: kmol/hr | D15: 0.012431187 | F15: =+D15/SUM($D$2:$D$73) -> 0.0019998023 | G15: =+D15/SUM($D$6:$D$73) -> 0.042353721 | N15: 0.0081042985
B16: C5-IP | C16: kmol/hr | D16: 0.00079740252 | F16: =+D16/SUM($D$2:$D$73) -> 0.00012827796 | G16: =+D16/SUM($D$6:$D$73) -> 0.0027167931 | N16: 0.00029194139
B17: C5-O | C17: kmol/hr | D17: 4.9454121e-20 | F17: =+D17/SUM($D$2:$D$73) -> 7.9556733e-21 | G17: =+D17/SUM($D$6:$D$73) -> 1.6849284e-19 | N17: 2.6819903e-20
... B73: C27 | C73: kmol/hr | D73: 0.010209164 | F73: =+D73/SUM($D$2:$D$73) -> 0.001642346 | G73: =+D73/SUM($D$6:$D$73) -> 0.03478317 | N73: 0.0096126591

Sheet Primary
B1: In | C1: Conversion | E1: Prod. Factor | F1: n | H1: CH4 | I1: MEOH | J1: C2 | K1: C2-O | L1: C3 | M1: C3-O | N1: C4 | O1: C4-IP | P1: C4-O | Q1: C5 | R1: C5-IP | S1: C5-O | T1: C5-N | U1: C6-IP | V1: C6 | W1: C6-O | X1: C6-A | Y1: C6-N | Z1: C7 | AA1: C7-IP | AB1: C7-O | AC1: C7-A | AD1: C7-N | AE1: C8 | AF1: C8-IP | AG1: C8-O | AH1: C8-N | AI1: C8-A | AJ1: C9 | AK1: C9-IP | AL1: C9-O | AM1: C9-N | AN1: C9-A | AO1: C10 | AP1: C10-IP | AQ1: C10-O | AR1: C10-N | AS1: C10-A | AT1: C11 | AU1: C11-IP | AV1: C11-A | AW1: C11-O | AX1: C12-IP | AY1: C12 | AZ1: C12-O | BA1: C12-A | BB1: C12-N | BC1: C13-IP | BD1: C13-O | BE1: C13 | BF1: C14-IP | BG1: C14 | BH1: C15-IP | BI1: C15 | BJ1: C16-IP | BK1: C16 | BL1: C17-IP | BM1: C17 | BN1: C18 | BO1: C19 | BP1: C20 | BQ1: C21 | BR1: C22 | BS1: C23 | BT1: C24 | BU1: C25 | BV1: C26 | BW1: C27 | BX1: C28 | BY1: C29 | BZ1: C30 | CA1: C31 | CB1: C32 | CC1: C33 | CD1: C34 | CE1: C35 | CF1: C36 | CG1: C37 | CH1: C38 | CI1: C39 | CJ1: C40 | CK1: C41 | CL1: C42 | CM1: C43 | CN1: C44 | CO1: C45 | CP1: C46 | CQ1: C48 | CR1: C50 | CS1: C51 | CT1: C52 | CU1: C54 | CV1: Out
A2: k | B2: =+Inlet!D6 -> 0.0007111447 | C2: 0 | E2: =B2 -> 0.0007111447 | F2: 1 | G2: CH4 | H2: =(1-$C2)*$B2 -> 0.0007111447 | CV2: {=TRANSPOSE(H96:CU96)} -> 0.0007111447 | CW2: CH4 | CY2: 0
A3: 0.4 | B3: =+Inlet!D7 -> 0.0011591573 | C3: 0 | E3: =B3 -> 0.0011591573 | F3: 1 | G3: MEOH | I3: =(1-$C3)*$B3 -> 0.0011591573 | CV3: 0.0011591573 | CW3: MEOH | CY3: 0
B4: =+Inlet!D8 -> 0.0025701201 | C4: 0 | E4: =B4 -> 0.0025701201 | F4: 2 | G4: C2 | J4: =(1-$C4)*$B4 -> 0.0025701201 | CV4: 0.0025701201 | CW4: C2 | CY4: 0
B5: =+Inlet!D9 -> 0 | C5: 0 | E5: =B5 -> 0 | F5: 2 | G5: C2-O | K5: =(1-$C5)*$B5 -> 0 | CV5: 0 | CW5: C2-O | CY5: 0
B6: =+Inlet!D10 -> 0.02379387 | C6: 0 | E6: =B6 -> 0.02379387 | F6: 3 | G6: C3 | L6: =(1-$C6)*$B6 -> 0.02379387 | CV6: 0.038202128 | CW6: C3 | CY6: 0
B7: =+Inlet!D11 -> 2.8280897e-09 | C7: 0 | E7: =B7 -> 2.8280897e-09 | F7: 3 | G7: C3-O | M7: =(1-$C7)*$B7 -> 2.8280897e-09 | CV7: 1.1449168e-08 | CW7: C3-O | CY7: 0
B8: =+Inlet!D12 -> 0.022656473 | C8: 0 | E8: =B8 -> 0.022656473 | F8: 4 | G8: C4 | N8: =(1-$C8)*$B8 -> 0.022656473 | CV8: 0.05215735 | CW8: C4 | CY8: 0
B9: =+Inlet!D13 -> 6.568806e-05 | C9: 0 | E9: =B9 -> 6.568806e-05 | F9: 4 | G9: C4-IP | O9: =(1-$C9)*$B9 -> 6.568806e-05 | CV9: 8.7688471e-05 | CW9: C4-IP | CY9: 0
B10: =+Inlet!D14 -> 8.1154749e-23 | C10: 0 | E10: =B10 -> 8.1154749e-23 | F10: 4 | G10: C4-O | P10: =(1-$C10)*$B10 -> 8.1154749e-23 | CV10: 8.1154749e-23 | CW10: C4-O | CY10: 0
B11: =+Inlet!D15 -> 0.012431187 | C11: 0 | E11: =B11 -> 0.012431187 | F11: 5 | G11: C5 | Q11: =(1-$C11)*$B11 -> 0.012431187 | CV11: 0.041243721 | CW11: C5 | CY11: 0
B12: =+Inlet!D16 -> 0.00079740252 | C12: 0 | E12: =B12 -> 0.00079740252 | F12: 5 | G12: C5-IP | R12: =(1-$C12)*$B12 -> 0.00079740252 | CV12: 0.00079740252 | CY12: 0
B13: =+Inlet!D17 -> 4.9454121e-20 | C13: 0 | E13: =B13 -> 4.9454121e-20 | F13: 5 | G13: C5-O | S13: =(1-$C13)*$B13 -> 4.9454121e-20 | CV13: 4.9454121e-20 | CW13: C5-O | CY13: 0
B14: =+Inlet!D18 -> 7.7846205e-05 | C14: 0 | E14: =B14 -> 7.7846205e-05 | F14: 5 | G14: C5-N | T14: =(1-$C14)*$B14 -> 7.7846205e-05 | CV14: 7.7846205e-05 | CY14: 0
B15: =+Inlet!D19 -> 0.0029408236 | C15: 0 | E15: =B15 -> 0.0029408236 | F15: 6 | G15: C6-IP | U15: =(1-$C15)*$B15 -> 0.0029408236 | CV15: 0.0029408236 | CW15: C6-IP | CY15: 0
B16: =+Inlet!D20 -> 0.0047346599 | C16: 0 | E16: =B16 -> 0.0047346599 | F16: 6 | G16: C6 | V16: =(1-$C16)*$B16 -> 0.0047346599 | CV16: 0.033540808 | CW16: C6 | CY16: 0
B17: =+Inlet!D21 -> 1.6313192e-17 | C17: 0 | E17: =B17 -> 1.6313192e-17 | F17: 6 | G17: C6-O | W17: =(1-$C17)*$B17 -> 1.6313192e-17 | CV17: 1.6313192e-17 | CW17: C6-O | CY17: =SUM(L17:S17)/2 -> 0
B18: =+Inlet!D22 -> 4.3282018e-19 | C18: 0 | E18: =B18 -> 4.3282018e-19 | F18: 6 | G18: C6-A | X18: =(1-$C18)*$B18 -> 4.3282018e-19 | CV18: 4.3282018e-19 | CY18: =SUM(L18:S18)/2 -> 0
B19: =+Inlet!D23 -> 0.0002096108 | C19: 0 | E19: =B19 -> 0.0002096108 | F19: 6 | G19: C6-N | Y19: =(1-$C19)*$B19 -> 0.0002096108 | CV19: 0.0002096108 | CY19: =SUM(L19:S19)/2 -> 0
B20: =+Inlet!D24 -> 0.0011693699 | C20: =(EXP($A$3*(F20-7))-1)/(EXP($A$3*(18-7))-1) -> 0 | D20: =1/(F20-6)*C20 -> 0 | E20: =B20 -> 0.0011693699 | F20: 7 | G20: C7 | Z20: =(1-$C20)*$B20 -> 0.0011693699 | CV20: 0.02997246 | CW20: C7 | CY20: =SUM(L20:S20)/2 -> 0
B21: =+Inlet!D25 -> 0.0014479776 | C21: =(EXP($A$3*(F21-7))-1)/(EXP($A$3*(18-7))-1) -> 0 | D21: =1/(F21-6)*C21 -> 0 | E21: =B21 -> 0.0014479776 | F21: 7 | G21: C7-IP | AA21: =(1-$C21)*$B21 -> 0.0014479776 | CV21: 0.0014479776 | CW21: C7-IP | CY21: =SUM(L21:S21)/2 -> 0
B22: =+Inlet!D26 -> 1.6154926e-15 | C22: =(EXP($A$3*(F22-7))-1)/(EXP($A$3*(18-7))-1) -> 0 | D22: =1/(F22-6)*C22 -> 0 | E22: =B22 -> 1.6154926e-15 | F22: 7 | G22: C7-O | AB22: =(1-$C22)*$B22 -> 1.6154926e-15 | CV22: 1.6154926e-15 | CW22: C7-O | CY22: =SUM(L22:S22)/2 -> 0
B23: =+Inlet!D27 -> 1.1090436e-15 | C23: =(EXP($A$3*(F23-7))-1)/(EXP($A$3*(18-7))-1) -> 0 | D23: =1/(F23-6)*C23 -> 0 | E23: =B23 -> 1.1090436e-15 | F23: 7 | G23: C7-A | AC23: =(1-$C23)*$B23 -> 1.1090436e-15 | CV23: 1.1090436e-15 | CW23: C7-A | CY23: =SUM(L23:S23)/2 -> 0
B24: =+Inlet!D28 -> 0.00019452524 | C24: =(EXP($A$3*(F24-7))-1)/(EXP($A$3*(18-7))-1) -> 0 | D24: =1/(F24-6)*C24 -> 0 | E24: =B24 -> 0.00019452524 | F24: 7 | G24: C7-N | AD24: =(1-$C24)*$B24 -> 0.00019452524 | CV24: 0.00019452524 | CY24: =SUM(L24:S24)/2 -> 0
B25: =+Inlet!D29 -> 0.00078531933 | C25: =(EXP($A$3*(F25-7))-1)/(EXP($A$3*(18-7))-1) -> 0.0061133547 | D25: =1/(F25-6)*C25 -> 0.0030566774 | E25: =1/(F25-6)*C25*B25 -> 2.4004678e-06 | F25: 8 | G25: C8 | L25: =+E25 -> 2.4004678e-06 | N25: =B2 -> 0.0007111447 | Q25: =+E25 -> 2.4004678e-06 | AE25: =(1-$C25)*$B25 -> 0.0007805184 | CV25: 0.029582865 | CW25: C8 | CY25: =SUM(L25:S25)/2 -> 0.00035797282
B26: =+Inlet!D30 -> 0.00052301839 | C26: =(EXP($A$3*(F26-7))-1)/(EXP($A$3*(18-7))-1) -> 0.0061133547 | D26: =1/(F26-6)*C26 -> 0.0030566774 | E26: =1/(F26-6)*C26*B26 -> 1.5986985e-06 | F26: 8 | G26: C8-IP | L26: =+E26 -> 1.5986985e-06 | O26: =+E26*2 -> 3.197397e-06 | Q26: =+E26 -> 1.5986985e-06 | AF26: =(1-$C26)*$B26 -> 0.000519821 | CV26: 0.000519821 | CW26: C8-IP | CY26: =SUM(L26:AA26)/2 -> 3.197397e-06
B27: =+Inlet!D31 -> 6.711039e-13 | C27: =(EXP($A$3*(F27-7))-1)/(EXP($A$3*(18-7))-1) -> 0.0061133547 | D27: =1/(F27-6)*C27 -> 0.0030566774 | E27: =1/(F27-6)*C27*B27 -> 2.0513481e-15 | F27: 8 | G27: C8-O | M27: =+E27 -> 2.0513481e-15 | N27: =+E27*2 -> 4.1026962e-15 | Q27: =+E27 -> 2.0513481e-15 | AG27: =(1-$C27)*$B27 -> 6.670012e-13 | CV27: 6.670012e-13 | CW27: C8-O | CY27: =SUM(L27:AA27)/2 -> 4.1026962e-15
B28: =+Inlet!D32 -> 0.00036401436 | C28: 0 | D28: =1/(F28-6)*C28 -> 0 | E28: =1/(F28-6)*C28*B28 -> 0 | F28: 8 | G28: C8-N | AH28: =(1-$C28)*$B28 -> 0.00036401436 | CV28: 0.00036401436 | CW28: C8-N | CY28: =SUM(L28:AA28)/2 -> 0
B29: =+Inlet!D33 -> 3.5532071e-12 | C29: 0 | D29: =1/(F29-6)*C29 -> 0 | E29: =1/(F29-6)*C29*B29 -> 0 | F29: 8 | G29: C8-A | AI29: =(1-$C29)*$B29 -> 3.5532071e-12 | CV29: 3.5532071e-12 | CW29: C8-A | CY29: =SUM(L29:AA29)/2 -> 0
B30: =+Inlet!D34 -> 0.0001336658 | C30: =(EXP($A$3*(F30-7))-1)/(EXP($A$3*(18-7))-1) -> 0.015233408 | D30: =1/(F30-6)*C30 -> 0.0050778028 | E30: =1/(F30-6)*C30*B30 -> 6.7872858e-07 | F30: 9 | G30: C9 | L30: =+E30 -> 6.7872858e-07 | N30: =+E30*2 -> 1.3574572e-06 | Q30: =+E30*2 -> 1.3574572e-06 | V30: =+E30 -> 6.7872858e-07 | AJ30: =(1-$C30)*$B30 -> 0.00013162962 | CV30: 0.02893382 | CW30: C9 | CY30: =SUM(L30:AA30)/2 -> 2.0361857e-06
B31: =+Inlet!D35 -> 0.00033641284 | C31: =(EXP($A$3*(F31-7))-1)/(EXP($A$3*(18-7))-1) -> 0.015233408 | D31: =1/(F31-6)*C31 -> 0.0050778028 | E31: =1/(F31-6)*C31*B31 -> 1.708238e-06 | F31: 9 | G31: C9-IP | L31: =+E31 -> 1.708238e-06 | O31: =+E31*2 -> 3.4164761e-06 | Q31: =+E31*2 -> 3.4164761e-06 | V31: =+E31 -> 1.708238e-06 | AK31: =(1-$C31)*$B31 -> 0.00033128812 | CV31: 0.00033128812 | CW31: C9-IP | CY31: =SUM(L31:AA31)/2 -> 5.1247141e-06
B32: =+Inlet!D36 -> 2.8889358e-11 | C32: =(EXP($A$3*(F32-7))-1)/(EXP($A$3*(18-7))-1) -> 0.015233408 | D32: =1/(F32-6)*C32 -> 0.0050778028 | E32: =1/(F32-6)*C32*B32 -> 1.4669446e-13 | F32: 9 | G32: C9-O | M32: =+E32 -> 1.4669446e-13 | N32: =+E32*2 -> 2.9338893e-13 | Q32: =+E32*2 -> 2.9338893e-13 | V32: =+E32 -> 1.4669446e-13 | AL32: =(1-$C32)*$B32 -> 2.8449275e-11 | CV32: 2.8449275e-11 | CW32: C9-O | CY32: =SUM(L32:AA32)/2 -> 4.4008339e-13
B33: =+Inlet!D37 -> 8.4212848e-05 | C33: 0 | D33: =1/(F33-6)*C33 -> 0 | E33: =1/(F33-6)*C33*B33 -> 0 | F33: 9 | G33: C9-N | AM33: =(1-$C33)*$B33 -> 8.4212848e-05 | CV33: 8.4212848e-05 | CW33: C9-N | CY33: =SUM(L33:AA33)/2 -> 0
B34: =+Inlet!D38 -> 6.2978784e-09 | C34: 0 | D34: =1/(F34-6)*C34 -> 0 | E34: =1/(F34-6)*C34*B34 -> 0 | F34: 9 | G34: C9-A | AN34: =(1-$C34)*$B34 -> 6.2978784e-09 | CV34: 6.2978784e-09 | CW34: C9-A | CY34: =SUM(L34:AA34)/2 -> 0
B35: =+Inlet!D39 -> 5.3126266e-05 | C35: =(EXP($A$3*(F35-7))-1)/(EXP($A$3*(18-7))-1) -> 0.028838929 | D35: =1/(F35-6)*C35 -> 0.0072097324 | E35: =1/(F35-6)*C35*B35 -> 3.8302616e-07 | F35: 10 | G35: C10 | L35: =+E35 -> 3.8302616e-07 | N35: =+E35*2 -> 7.6605232e-07 | Q35: =+E35*2 -> 7.6605232e-07 | V35: =+E35*2 -> 7.6605232e-07 | Z35: =+E35 -> 3.8302616e-07 | AO35: =(1-$C35)*$B35 -> 5.1594161e-05 | CV35: 0.028853411 | CW35: C10 | CY35: =SUM(L35:AA35)/2 -> 1.5321046e-06
B36: =+Inlet!D40 -> 3.9899902e-05 | C36: =(EXP($A$3*(F36-7))-1)/(EXP($A$3*(18-7))-1) -> 0.028838929 | D36: =1/(F36-6)*C36 -> 0.0072097324 | E36: =1/(F36-6)*C36*B36 -> 2.8766761e-07 | F36: 10 | G36: C10-IP | L36: =+E36 -> 2.8766761e-07 | O36: =+E36*2 -> 5.7533522e-07 | Q36: =+E36*2 -> 5.7533522e-07 | V36: =+E36*2 -> 5.7533522e-07 | Z36: =+E36 -> 2.8766761e-07 | AP36: =(1-$C36)*$B36 -> 3.8749231e-05 | CV36: 3.8749231e-05 | CW36: C10-IP | CY36: =SUM(L36:AA36)/2 -> 1.1506704e-06
B37: =+Inlet!D41 -> 2.900543e-08 | C37: =(EXP($A$3*(F37-7))-1)/(EXP($A$3*(18-7))-1) -> 0.028838929 | D37: =1/(F37-6)*C37 -> 0.0072097324 | E37: =1/(F37-6)*C37*B37 -> 2.0912139e-10 | F37: 10 | G37: C10-O | M37: =+E37 -> 2.0912139e-10 | N37: =+E37*2 -> 4.1824277e-10 | Q37: =+E37*2 -> 4.1824277e-10 | V37: =+E37*2 -> 4.1824277e-10 | Z37: =+E37 -> 2.0912139e-10 | AQ37: =(1-$C37)*$B37 -> 2.8168944e-08 | CV37: 2.8168944e-08 | CW37: C10-O | CY37: =SUM(L37:AK37)/2 -> 8.3648555e-10
B38: =+Inlet!D42 -> 1.2093808e-05 | C38: 0 | D38: =1/(F38-6)*C38 -> 0 | E38: =1/(F38-6)*C38*B38 -> 0 | F38: 10 | G38: C10-N | AR38: =(1-$C38)*$B38 -> 1.2093808e-05 | CV38: 1.2093808e-05 | CW38: C10-N | CY38: =SUM(L38:AK38)/2 -> 0
B39: =+Inlet!D43 -> 3.2000963e-07 | C39: 0 | D39: =1/(F39-6)*C39 -> 0 | E39: =1/(F39-6)*C39*B39 -> 0 | F39: 10 | G39: C10-A | AS39: =(1-$C39)*$B39 -> 3.2000963e-07 | CV39: 3.2000963e-07 | CW39: C10-A | CY39: =SUM(L39:AK39)/2 -> 0
B40: =+Inlet!D44 -> 6.3675358e-06 | C40: =(EXP($A$3*(F40-7))-1)/(EXP($A$3*(18-7))-1) -> 0.049135982 | D40: =1/(F40-6)*C40 -> 0.0098271964 | E40: =1/(F40-6)*C40*B40 -> 6.2575025e-08 | F40: 11 | G40: C11 | L40: =+E40 -> 6.2575025e-08 | N40: =+E40*2 -> 1.2515005e-07 | Q40: =+E40*2 -> 1.2515005e-07 | V40: =+E40*2 -> 1.2515005e-07 | Z40: =+E40*2 -> 1.2515005e-07 | AE40: =+E40 -> 6.2575025e-08 | AT40: =(1-$C40)*$B40 -> 6.0546607e-06 | CV40: 0.028806019 | CW40: C11 | CY40: =SUM(L40:AK40)/2 -> 3.1287512e-07
...

Sheet Secondary
B1: In | C1: Conversion | E1: Prod. Factor | F1: n | H1: CH4 | I1: MEOH | J1: C2 | K1: C2-O | L1: C3 | M1: C3-O | N1: C4 | O1: C4-IP | P1: C4-O | Q1: C5 | R1: C5-IP | S1: C5-O | T1: C5-N | U1: C6-IP | V1: C6 | W1: C6-O | X1: C6-A | Y1: C6-N | Z1: C7 | AA1: C7-IP | AB1: C7-O | AC1: C7-A | AD1: C7-N | AE1: C8 | AF1: C8-IP | AG1: C8-O | AH1: C8-N | AI1: C8-A | AJ1: C9 | AK1: C9-IP | AL1: C9-O | AM1: C9-N | AN1: C9-A | AO1: C10 | AP1: C10-IP | AQ1: C10-O | AR1: C10-N | AS1: C10-A | AT1: C11 | AU1: C11-IP | AV1: C11-A | AW1: C11-O | AX1: C12-IP | AY1: C12 | AZ1: C12-O | BA1: C12-A | BB1: C12-N | BC1: C13-IP | BD1: C13-O | BE1: C13 | BF1: C14-IP | BG1: C14 | BH1: C15-IP | BI1: C15 | BJ1: C16-IP | BK1: C16 | BL1: C17-IP | BM1: C17 | BN1: C18 | BO1: C19 | BP1: C20 | BQ1: C21 | BR1: C22 | BS1: C23 | BT1: C24 | BU1: C25 | BV1: C26 | BW1: C27 | BX1: C28 | BY1: C29 | BZ1: C30 | CA1: C31 | CB1: C32 | CC1: C33 | CD1: C34 | CE1: C35 | CF1: C36 | CG1: C37 | CH1: C38 | CI1: C39 | CJ1: C40 | CK1: C41 | CL1: C42 | CM1: C43 | CN1: C44 | CO1: C45 | CP1: C46 | CQ1: C48 | CR1: C50 | CS1: C51 | CT1: C52 | CU1: C54 | CV1: Out
A2: k | B2: =Primary!CV2 -> 0.0007111447 | C2: 0 | E2: =B2 -> 0.0007111447 | F2: 1 | G2: CH4 | H2: =(1-$C2)*$B2 -> 0.0007111447 | CV2: {=TRANSPOSE(H96:CU96)} -> 0.0007111447 | CW2: CH4 | CY2: 0
A3: 0.4 | B3: =Primary!CV3 -> 0.0011591573 | C3: 0 | E3: =B3 -> 0.0011591573 | F3: 1 | G3: MEOH | I3: =(1-$C3)*$B3 -> 0.0011591573 | CV3: 0.0011591573 | CW3: MEOH | CY3: 0
B4: =Primary!CV4 -> 0.0025701201 | C4: 0 | E4: =B4 -> 0.0025701201 | F4: 2 | G4: C2 | J4: =(1-$C4)*$B4 -> 0.0025701201 | CV4: 0.0025701201 | CW4: C2 | CY4: 0
B5: =Primary!CV5 -> 0 | C5: =C504 -> 0 | E5: =B5 -> 0 | F5: 2 | G5: C2-O | K5: =(1-$C5)*$B5 -> 0 | CV5: 0 | CW5: C2-O | CY5: 0
B6: =Primary!CV6 -> 0.038202128 | C6: 0 | E6: =B6 -> 0.038202128 | F6: 3 | G6: C3 | L6: =(1-$C6)*$B6 -> 0.038202128 | CV6: 0.046010388 | CW6: C3 | CY6: 0
B7: =Primary!CV7 -> 1.1449168e-08 | C7: 0 | E7: =B7 -> 1.1449168e-08 | F7: 3 | G7: C3-O | M7: =(1-$C7)*$B7 -> 1.1449168e-08 | CV7: 1.6611307e-08 | CW7: C3-O | CY7: 0
B8: =Primary!CV8 -> 0.05215735 | C8: 0 | E8: =B8 -> 0.05215735 | F8: 4 | G8: C4 | N8: =(1-$C8)*$B8 -> 0.05215735 | CV8: 0.067760038 | CW8: C4 | CY8: 0
B9: =Primary!CV9 -> 8.7688471e-05 | C9: 0 | E9: =B9 -> 8.7688471e-05 | F9: 4 | G9: C4-IP | O9: =(1-$C9)*$B9 -> 8.7688471e-05 | CV9: 0.00010153019 | CW9: C4-IP | CY9: 0
B10: =Primary!CV10 -> 8.1154749e-23 | C10: 0 | E10: =B10 -> 8.1154749e-23 | F10: 4 | G10: C4-O | P10: =(1-$C10)*$B10 -> 8.1154749e-23 | CV10: 8.1154749e-23 | CW10: C4-O | CY10: 0
B11: =Primary!CV11 -> 0.041243721 | C11: 0 | E11: =B11 -> 0.041243721 | F11: 5 | G11: C5 | Q11: =(1-$C11)*$B11 -> 0.041243721 | CV11: 0.056768236 | CW11: C5 | CY11: 0
B12: =Primary!CV12 -> 0.00079740252 | C12: 0 | E12: =B12 -> 0.00079740252 | F12: 5 | G12: C5-IP | R12: =(1-$C12)*$B12 -> 0.00079740252 | CV12: 0.00079740252 | CY12: 0
B13: =Primary!CV13 -> 4.9454121e-20 | C13: 0 | E13: =B13 -> 4.9454121e-20 | F13: 5 | G13: C5-O | S13: =(1-$C13)*$B13 -> 4.9454121e-20 | CV13: 4.9454121e-20 | CW13: C5-O | CY13: 0
B14: =Primary!CV14 -> 7.7846205e-05 | C14: 0 | E14: =B14 -> 7.7846205e-05 | F14: 5 | G14: C5-N | T14: =(1-$C14)*$B14 -> 7.7846205e-05 | CV14: 7.7846205e-05 | CY14: 0
B15: =Primary!CV15 -> 0.0029408236 | C15: 0 | E15: =B15 -> 0.0029408236 | F15: 6 | G15: C6-IP | U15: =(1-$C15)*$B15 -> 0.0029408236 | CV15: 0.0029408236 | CW15: C6-IP | CY15: 0
B16: =Primary!CV16 -> 0.033540808 | C16: 0 | E16: =B16 -> 0.033540808 | F16: 6 | G16: C6 | V16: =(1-$C16)*$B16 -> 0.033540808 | CV16: 0.048824706 | CW16: C6 | CY16: 0
B17: =Primary!CV17 -> 1.6313192e-17 | C17: 0 | E17: =B17 -> 1.6313192e-17 | F17: 6 | G17: C6-O | W17: =(1-$C17)*$B17 -> 1.6313192e-17 | CV17: 1.6313192e-17 | CW17: C6-O | CY17: =SUM(L17:S17)/2 -> 0
B18: =Primary!CV18 -> 4.3282018e-19 | C18: 0 | E18: =B18 -> 4.3282018e-19 | F18: 6 | G18: C6-A | X18: =(1-$C18)*$B18 -> 4.3282018e-19 | CV18: 4.3282018e-19 | CY18: =SUM(L18:S18)/2 -> 0
B19: =Primary!CV19 -> 0.0002096108 | C19: 0 | E19: =B19 -> 0.0002096108 | F19: 6 | G19: C6-N | Y19: =(1-$C19)*$B19 -> 0.0002096108 | CV19: 0.0002096108 | CY19: =SUM(L19:S19)/2 -> 0
B20: =Primary!CV20 -> 0.02997246 | C20: =(EXP($A$3*(F20-7))-1)/(EXP($A$3*(18-7))-1) -> 0 | D20: =1/(F20-6)*C20 -> 0 | E20: =B20 -> 0.02997246 | F20: 7 | G20: C7 | Z20: =(1-$C20)*$B20 -> 0.02997246 | CV20: 0.044899451 | CW20: C7 | CY20: =SUM(L20:S20)/2 -> 0
B21: =Primary!CV21 -> 0.0014479776 | C21: =(EXP($A$3*(F21-7))-1)/(EXP($A$3*(18-7))-1) -> 0 | D21: =1/(F21-6)*C21 -> 0 | E21: =B21 -> 0.0014479776 | F21: 7 | G21: C7-IP | AA21: =(1-$C21)*$B21 -> 0.0014479776 | CV21: 0.0014479776 | CW21: C7-IP | CY21: =SUM(L21:S21)/2 -> 0
B22: =Primary!CV22 -> 1.6154926e-15 | C22: =(EXP($A$3*(F22-7))-1)/(EXP($A$3*(18-7))-1) -> 0 | D22: =1/(F22-6)*C22 -> 0 | E22: =B22 -> 1.6154926e-15 | F22: 7 | G22: C7-O | AB22: =(1-$C22)*$B22 -> 1.6154926e-15 | CV22: 1.6154926e-15 | CW22: C7-O | CY22: =SUM(L22:S22)/2 -> 0
B23: =Primary!CV23 -> 1.1090436e-15 | C23: 0 | D23: =1/(F23-6)*C23 -> 0 | E23: =B23 -> 1.1090436e-15 | F23: 7 | G23: C7-A | AC23: =(1-$C23)*$B23 -> 1.1090436e-15 | CV23: 1.1090436e-15 | CW23: C7-A | CY23: =SUM(L23:S23)/2 -> 0
B24: =Primary!CV24 -> 0.00019452524 | C24: 0 | D24: =1/(F24-6)*C24 -> 0 | E24: =B24 -> 0.00019452524 | F24: 7 | G24: C7-N | AD24: =(1-$C24)*$B24 -> 0.00019452524 | CV24: 0.00019452524 | CY24: =SUM(L24:S24)/2 -> 0
B25: =Primary!CV25 -> 0.029582865 | C25: =(EXP($A$3*(F25-7))-1)/(EXP($A$3*(18-7))-1) -> 0.0061133547 | D25: =1/(F25-6)*C25 -> 0.0030566774 | E25: =1/(F25-6)*C25*B25 -> 9.0425274e-05 | F25: 8 | G25: C8 | L25: =+E25 -> 9.0425274e-05 | N25: =+E25*2 -> 0.00018085055 | Q25: =+E25 -> 9.0425274e-05 | AE25: =(1-$C25)*$B25 -> 0.029402015 | CV25: 0.043837612 | CW25: C8 | CY25: =SUM(L25:S25)/2 -> 0.00018085055
B26: =Primary!CV26 -> 0.000519821 | C26: =(EXP($A$3*(F26-7))-1)/(EXP($A$3*(18-7))-1) -> 0.0061133547 | D26: =1/(F26-6)*C26 -> 0.0030566774 | E26: =1/(F26-6)*C26*B26 -> 1.5889251e-06 | F26: 8 | G26: C8-IP | L26: =+E26 -> 1.5889251e-06 | O26: =+E26*2 -> 3.1778501e-06 | Q26: =+E26 -> 1.5889251e-06 | AF26: =(1-$C26)*$B26 -> 0.00051664315 | CV26: 0.00051664315 | CW26: C8-IP | CY26: =SUM(L26:AA26)/2 -> 3.1778501e-06
B27: =Primary!CV27 -> 6.670012e-13 | C27: =(EXP($A$3*(F27-7))-1)/(EXP($A$3*(18-7))-1) -> 0.0061133547 | D27: =1/(F27-6)*C27 -> 0.0030566774 | E27: =1/(F27-6)*C27*B27 -> 2.0388075e-15 | F27: 8 | G27: C8-O | M27: =+E27 -> 2.0388075e-15 | N27: =+E27*2 -> 4.0776149e-15 | Q27: =+E27 -> 2.0388075e-15 | AG27: =(1-$C27)*$B27 -> 6.6292358e-13 | CV27: 6.6292358e-13 | CW27: C8-O | CY27: =SUM(L27:AA27)/2 -> 4.0776149e-15
B28: =Primary!CV28 -> 0.00036401436 | C28: 0 | D28: =1/(F28-6)*C28 -> 0 | E28: =1/(F28-6)*C28*B28 -> 0 | F28: 8 | G28: C8-N | AH28: =(1-$C28)*$B28 -> 0.00036401436 | CV28: 0.00036401436 | CW28: C8-N | CY28: =SUM(L28:AA28)/2 -> 0
B29: =Primary!CV29 -> 3.5532071e-12 | C29: 0 | D29: =1/(F29-6)*C29 -> 0 | E29: =1/(F29-6)*C29*B29 -> 0 | F29: 8 | G29: C8-A | AI29: =(1-$C29)*$B29 -> 3.5532071e-12 | CV29: 3.5532071e-12 | CW29: C8-A | CY29: =SUM(L29:AA29)/2 -> 0
B30: =Primary!CV30 -> 0.02893382 | C30: =(EXP($A$3*(F30-7))-1)/(EXP($A$3*(18-7))-1) -> 0.015233408 | D30: =1/(F30-6)*C30 -> 0.0050778028 | E30: =1/(F30-6)*C30*B30 -> 0.00014692023 | F30: 9 | G30: C9 | L30: =+E30 -> 0.00014692023 | N30: =+E30*2 -> 0.00029384046 | Q30: =+E30*2 -> 0.00029384046 | V30: =+E30 -> 0.00014692023 | AJ30: =(1-$C30)*$B30 -> 0.028493059 | CV30: 0.042264427 | CW30: C9 | CY30: =SUM(L30:AA30)/2 -> 0.0004407607
B31: =Primary!CV31 -> 0.00033128812 | C31: =(EXP($A$3*(F31-7))-1)/(EXP($A$3*(18-7))-1) -> 0.015233408 | D31: =1/(F31-6)*C31 -> 0.0050778028 | E31: =1/(F31-6)*C31*B31 -> 1.6822157e-06 | F31: 9 | G31: C9-IP | L31: =+E31 -> 1.6822157e-06 | O31: =+E31*2 -> 3.3644315e-06 | Q31: =+E31*2 -> 3.3644315e-06 | V31: =+E31 -> 1.6822157e-06 | AK31: =(1-$C31)*$B31 -> 0.00032624148 | CV31: 0.00032624148 | CW31: C9-IP | CY31: =SUM(L31:AA31)/2 -> 5.0466472e-06
B32: =Primary!CV32 -> 2.8449275e-11 | C32: =(EXP($A$3*(F32-7))-1)/(EXP($A$3*(18-7))-1) -> 0.015233408 | D32: =1/(F32-6)*C32 -> 0.0050778028 | E32: =1/(F32-6)*C32*B32 -> 1.4445981e-13 | F32: 9 | G32: C9-O | M32: =+E32 -> 1.4445981e-13 | N32: =+E32*2 -> 2.8891961e-13 | Q32: =+E32*2 -> 2.8891961e-13 | V32: =+E32 -> 1.4445981e-13 | AL32: =(1-$C32)*$B32 -> 2.8015896e-11 | CV32: 2.8015896e-11 | CW32: C9-O | CY32: =SUM(L32:AA32)/2 -> 4.3337942e-13
B33: =Primary!CV33 -> 8.4212848e-05 | C33: 0 | D33: =1/(F33-6)*C33 -> 0 | E33: =1/(F33-6)*C33*B33 -> 0 | F33: 9 | G33: C9-N | AM33: =(1-$C33)*$B33 -> 8.4212848e-05 | CV33: 8.4212848e-05 | CW33: C9-N | CY33: =SUM(L33:AA33)/2 -> 0
B34: =Primary!CV34 -> 6.2978784e-09 | C34: 0 | D34: =1/(F34-6)*C34 -> 0 | E34: =1/(F34-6)*C34*B34 -> 0 | F34: 9 | G34: C9-A | AN34: =(1-$C34)*$B34 -> 6.2978784e-09 | CV34: 6.2978784e-09 | CW34: C9-A | CY34: =SUM(L34:AA34)/2 -> 0
B35: =Primary!CV35 -> 0.028853411 | C35: =(EXP($A$3*(F35-7))-1)/(EXP($A$3*(18-7))-1) -> 0.028838929 | D35: =1/(F35-6)*C35 -> 0.0072097324 | E35: =1/(F35-6)*C35*B35 -> 0.00020802537 | F35: 10 | G35: C10 | L35: =+E35 -> 0.00020802537 | N35: =+E35*2 -> 0.00041605074 | Q35: =+E35*2 -> 0.00041605074 | V35: =+E35*2 -> 0.00041605074 | Z35: =+E35 -> 0.00020802537 | AO35: =(1-$C35)*$B35 -> 0.028021309 | CV35: 0.040899806 | CW35: C10 | CY35: =SUM(L35:AA35)/2 -> 0.00083210147
B36: =Primary!CV36 -> 3.8749231e-05 | C36: =(EXP($A$3*(F36-7))-1)/(EXP($A$3*(18-7))-1) -> 0.028838929 | D36: =1/(F36-6)*C36 -> 0.0072097324 | E36: =1/(F36-6)*C36*B36 -> 2.7937159e-07 | F36: 10 | G36: C10-IP | L36: =+E36 -> 2.7937159e-07 | O36: =+E36*2 -> 5.5874317e-07 | Q36: =+E36*2 -> 5.5874317e-07 | V36: =+E36*2 -> 5.5874317e-07 | Z36: =+E36 -> 2.7937159e-07 | AP36: =(1-$C36)*$B36 -> 3.7631745e-05 | CV36: 3.7631745e-05 | CW36: C10-IP | CY36: =SUM(L36:AA36)/2 -> 1.1174863e-06
B37: =Primary!CV37 -> 2.8168944e-08 | C37: =(EXP($A$3*(F37-7))-1)/(EXP($A$3*(18-7))-1) -> 0.028838929 | D37: =1/(F37-6)*C37 -> 0.0072097324 | E37: =1/(F37-6)*C37*B37 -> 2.0309055e-10 | F37: 10 | G37: C10-O | M37: =+E37 -> 2.0309055e-10 | N37: =+E37*2 -> 4.061811e-10 | Q37: =+E37*2 -> 4.061811e-10 | V37: =+E37*2 -> 4.061811e-10 | Z37: =+E37 -> 2.0309055e-10 | AQ37: =(1-$C37)*$B37 -> 2.7356582e-08 | CV37: 2.7356582e-08 | CW37: C10-O | CY37: =SUM(L37:AK37)/2 -> 8.123622e-10
B38: =Primary!CV38 -> 1.2093808e-05 | C38: 0 | D38: =1/(F38-6)*C38 -> 0 | E38: =1/(F38-6)*C38*B38 -> 0 | F38: 10 | G38: C10-N | AR38: =(1-$C38)*$B38 -> 1.2093808e-05 | CV38: 1.2093808e-05 | CW38: C10-N | CY38: =SUM(L38:AK38)/2 -> 0
B39: =Primary!CV39 -> 3.2000963e-07 | C39: 0 | D39: =1/(F39-6)*C39 -> 0 | E39: =1/(F39-6)*C39*B39 -> 0 | F39: 10 | G39: C10-A | AS39: =(1-$C39)*$B39 -> 3.2000963e-07 | CV39: 3.2000963e-07 | CW39: C10-A | CY39: =SUM(L39:AK39)/2 -> 0
B40: =Primary!CV40 -> 0.028806019 | C40: =(EXP($A$3*(F40-7))-1)/(EXP($A$3*(18-7))-1) -> 0.049135982 | D40: =1/(F40-6)*C40 -> 0.0098271964 | E40: =1/(F40-6)*C40*B40 -> 0.00028308241 | F40: 11 | G40: C11 | L40: =+E40 -> 0.00028308241 | N40: =+E40*2 -> 0.00056616481 | Q40: =+E40*2 -> 0.00056616481 | V40: =+E40*2 -> 0.00056616481 | Z40: =+E40*2 -> 0.00056616481 | AE40: =+E40 -> 0.00028308241 | AT40: =(1-$C40)*$B40 -> 0.027390607 | CV40: 0.03907429 | CW40: C11 | CY40: =SUM(L40:AK40)/2 -> 0.001415412
...

Sheet Outlet
B2: CO2 | C2: kmol/hr | D2: =+Inlet!D2 -> 0.086674785 | F2: =+D2/SUM($D$2:$D$73) -> 0.013942561 | K2: 0,015188681638455
B3: H2O | C3: kmol/hr | D3: =+Inlet!D3 -> 0.0060443607 | F3: =+D3/SUM($D$2:$D$73) -> 0.00097229971 | K3: 0,00373424142390863
B4: H2 | C4: kmol/hr | D4: =+Inlet!D4-Primary!CY96-Secondary!CY96 -> 5.5367353 | F4: =+D4/SUM($D$2:$D$73) -> 0.89064277 | K4: 5,84918770555721
B5: CO | C5: kmol/hr | D5: =+Inlet!D5 -> 4.8714785e-05 | F5: =+D5/SUM($D$2:$D$73) -> 7.8362913e-06 | K5: 2,16390322899192E-06
B6: CH4 | C6: kmol/hr | D6: =+Secondary!CV2 -> 0.0007111447 | F6: =+D6/SUM($D$2:$D$73) -> 0.00011439519 | G6: =+D6/SUM($D$6:$D$73) -> 0.0012113703 | K6: 0,0000471898648045363
B7: MEOH | C7: kmol/hr | D7: =+Secondary!CV3 -> 0.0011591573 | F7: =+D7/SUM($D$2:$D$73) -> 0.00018646278 | G7: =+D7/SUM($D$6:$D$73) -> 0.0019745189 | K7: 0,000671995167802076
B8: C2 | C8: kmol/hr | D8: =+Secondary!CV4 -> 0.0025701201 | F8: =+D8/SUM($D$2:$D$73) -> 0.00041343115 | G8: =+D8/SUM($D$6:$D$73) -> 0.0043779656 | K8: 0,000519980199463744
B9: C2-O | C9: kmol/hr | D9: =+Secondary!CV5 -> 0 | F9: =+D9/SUM($D$2:$D$73) -> 0 | G9: =+D9/SUM($D$6:$D$73) -> 0 | K9: 0
B10: C3 | C10: kmol/hr | D10: =+Secondary!CV6 -> 0.046010388 | F10: =+D10/SUM($D$2:$D$73) -> 0.0074012603 | G10: =+D10/SUM($D$6:$D$73) -> 0.078374507 | K10: 0,013075764899568
B11: C3-O | C11: kmol/hr | D11: =+Secondary!CV7 -> 1.6611307e-08 | F11: =+D11/SUM($D$2:$D$73) -> 2.6721054e-09 | G11: =+D11/SUM($D$6:$D$73) -> 2.8295849e-08 | K11: 5,74855733595377E-09
B12: C4 | C12: kmol/hr | D12: =+Secondary!CV8 -> 0.067760038 | F12: =+D12/SUM($D$2:$D$73) -> 0.010899923 | G12: =+D12/SUM($D$6:$D$73) -> 0.11542306 | K12: 0,0236083428410457
B13: C4-IP | C13: kmol/hr | D13: =+Secondary!CV9 -> 0.00010153019 | F13: =+D13/SUM($D$2:$D$73) -> 1.6332211e-05 | G13: =+D13/SUM($D$6:$D$73) -> 0.00017294743 | K13: 0,000045972522974249
B14: C4-O | C14: kmol/hr | D14: =+Secondary!CV10 -> 8.1154749e-23 | F14: =+D14/SUM($D$2:$D$73) -> 1.3054605e-23 | G14: =+D14/SUM($D$6:$D$73) -> 1.3823973e-22 | K14: 3,91867738433925E-23
B15: C5 | C15: kmol/hr | D15: =+Secondary!CV11 -> 0.056768236 | F15: =+D15/SUM($D$2:$D$73) -> 0.0091317747 | G15: =+D15/SUM($D$6:$D$73) -> 0.096699523 | K15: 0,0215417024427832
B16: C5-IP | C16: kmol/hr | D16: =+Secondary!CV12 -> 0.00079740252 | F16: =+D16/SUM($D$2:$D$73) -> 0.00012827068 | G16: =+D16/SUM($D$6:$D$73) -> 0.0013583026 | K16: 0,00029185059620702
B17: C5-O | C17: kmol/hr | D17: =+Secondary!CV13 -> 4.9454121e-20 | F17: =+D17/SUM($D$2:$D$73) -> 7.9552214e-21 | G17: =+D17/SUM($D$6:$D$73) -> 8.4240593e-20 | K17: 2,65771162208618E-20
B18: C5-N | C18: kmol/hr | D18: =+Secondary!CV14 -> 7.7846205e-05 | F18: =+D18/SUM($D$2:$D$73) -> 1.252239e-05 | G18: =+D18/SUM($D$6:$D$73) -> 0.00013260392 | K18: 0,0000505173989059497
B19: C6-IP | C19: kmol/hr | D19: =+Secondary!CV15 -> 0.0029408236 | F19: =+D19/SUM($D$2:$D$73) -> 0.00047306276 | G19: =+D19/SUM($D$6:$D$73) -> 0.0050094254 | K19: 0,00239039050368725
B20: C6 | C20: kmol/hr | D20: =+Secondary!CV16 -> 0.048824706 | F20: =+D20/SUM($D$2:$D$73) -> 0.0078539734 | G20: =+D20/SUM($D$6:$D$73) -> 0.083168443 | K20: 0,0161077106578016
B21: C6-O | C21: kmol/hr | D21: =+Secondary!CV17 -> 1.6313192e-17 | F21: =+D21/SUM($D$2:$D$73) -> 2.6241505e-18 | G21: =+D21/SUM($D$6:$D$73) -> 2.7788038e-17 | K21: 6,34937228107811E-18
... B67: C21 | C67: kmol/hr | D67: =+Secondary!CV63 -> 2.7008371e-05 | F67: =+D67/SUM($D$2:$D$73) -> 4.3445838e-06 | G67: =+D67/SUM($D$6:$D$73) -> 4.6006302e-05 | K67: 6,35746709183344E-06
B68: C22 | C68: kmol/hr | D68: =+Secondary!CV64 -> 0 | F68: =+D68/SUM($D$2:$D$73) -> 0 | G68: =+D68/SUM($D$6:$D$73) -> 0 | K68: 0
B69: C23 | C69: kmol/hr | D69: =+Secondary!CV65 -> 0 | F69: =+D69/SUM($D$2:$D$73) -> 0 | G69: =+D69/SUM($D$6:$D$73) -> 0 | K69: 0
B70: C24 | C70: kmol/hr | D70: =+Secondary!CV66 -> 0 | F70: =+D70/SUM($D$2:$D$73) -> 0 | G70: =+D70/SUM($D$6:$D$73) -> 0 | K70: 0
B71: C25 | C71: kmol/hr | D71: =+Secondary!CV67 -> 0 | F71: =+D71/SUM($D$2:$D$73) -> 0 | G71: =+D71/SUM($D$6:$D$73) -> 0 | K71: 0
B72: C26 | C72: kmol/hr | D72: =+Secondary!CV68 -> 0 | F72: =+D72/SUM($D$2:$D$73) -> 0 | G72: =+D72/SUM($D$6:$D$73) -> 0 | K72: 0
B73: C27 | C73: kmol/hr | D73: =+Secondary!CV69 -> 0 | F73: =+D73/SUM($D$2:$D$73) -> 0 | G73: =+D73/SUM($D$6:$D$73) -> 0 | K73: 0

Sheet Pivot
C3: Name | D3: NC | E3: Inlet | F3: Primary | G3: Secondary
C4: CH4 | D4: 1 | E4: =+Inlet!D6 -> 0.0007111447 | F4: =+Secondary!B2 -> 0.0007111447 | G4: =+Outlet!D6 -> 0.0007111447 | AF4: =+Tabella4[[#This Row],[Inlet]]*Tabella4[[#This Row],[NC]] -> 0.0007111447 | AG4: =+Tabella4[[#This Row],[Primary]]*Tabella4[[#This Row],[NC]] -> 0.0007111447 | AH4: =+Tabella4[[#This Row],[Secondary]]*Tabella4[[#This Row],[NC]] -> 0.0007111447
C5: MEOH | D5: 1 | E5: =+Inlet!D7 -> 0.0011591573 | F5: =+Secondary!B3 -> 0.0011591573 | G5: =+Outlet!D7 -> 0.0011591573 | AF5: =+Tabella4[[#This Row],[Inlet]]*Tabella4[[#This Row],[NC]] -> 0.0011591573 | AG5: =+Tabella4[[#This Row],[Primary]]*Tabella4[[#This Row],[NC]] -> 0.0011591573 | AH5: =+Tabella4[[#This Row],[Secondary]]*Tabella4[[#This Row],[NC]] -> 0.0011591573
C6: C2 | D6: 2 | E6: =+Inlet!D8 -> 0.0025701201 | F6: =+Secondary!B4 -> 0.0025701201 | G6: =+Outlet!D8 -> 0.0025701201 | AF6: =+Tabella4[[#This Row],[Inlet]]*Tabella4[[#This Row],[NC]] -> 0.0051402401 | AG6: =+Tabella4[[#This Row],[Primary]]*Tabella4[[#This Row],[NC]] -> 0.0051402401 | AH6: =+Tabella4[[#This Row],[Secondary]]*Tabella4[[#This Row],[NC]] -> 0.0051402401
C7: C2-O | D7: 2 | E7: =+Inlet!D9 -> 0 | F7: =+Secondary!B5 -> 0 | G7: =+Outlet!D9 -> 0 | J7: Etichette di riga | K7: Somma di Inlet | L7: Somma di Primary | M7: Somma di Secondary | AF7: =+Tabella4[[#This Row],[Inlet]]*Tabella4[[#This Row],[NC]] -> 0 | AG7: =+Tabella4[[#This Row],[Primary]]*Tabella4[[#This Row],[NC]] -> 0 | AH7: =+Tabella4[[#This Row],[Secondary]]*Tabella4[[#This Row],[NC]] -> 0
C8: C3 | D8: 3 | E8: =+Inlet!D10 -> 0.02379387 | F8: =+Secondary!B6 -> 0.038202128 | G8: =+Outlet!D10 -> 0.046010388 | J8: 1 | K8: 0.0063722191 | L8: 0.0036862072 | M8: 0.003189727 | P8: 1 | Q8: 0.0063722191 | R8: 0.0036862072 | S8: 0.003189727 | AF8: =+Tabella4[[#This Row],[Inlet]]*Tabella4[[#This Row],[NC]] -> 0.071381611 | AG8: =+Tabella4[[#This Row],[Primary]]*Tabella4[[#This Row],[NC]] -> 0.11460638 | AH8: =+Tabella4[[#This Row],[Secondary]]*Tabella4[[#This Row],[NC]] -> 0.13803116
C9: C3-O | D9: 3 | E9: =+Inlet!D11 -> 2.8280897e-09 | F9: =+Secondary!B7 -> 1.1449168e-08 | G9: =+Outlet!D11 -> 1.6611307e-08 | J9: 2 | K9: 0.0087565369 | L9: 0.0050654895 | M9: 0.0043832395 | P9: 2 | Q9: 0.0087565369 | R9: 0.0050654895 | S9: 0.0043832395 | AF9: =+Tabella4[[#This Row],[Inlet]]*Tabella4[[#This Row],[NC]] -> 8.4842692e-09 | AG9: =+Tabella4[[#This Row],[Primary]]*Tabella4[[#This Row],[NC]] -> 3.4347504e-08 | AH9: =+Tabella4[[#This Row],[Secondary]]*Tabella4[[#This Row],[NC]] -> 4.9833921e-08
C10: C4 | D10: 4 | E10: =+Inlet!D12 -> 0.022656473 | F10: =+Secondary!B8 -> 0.05215735 | G10: =+Outlet!D12 -> 0.067760038 | J10: 3 | K10: 0.081067002 | L10: 0.07529319 | M10: 0.078468949 | P10: 3 | Q10: 0.081067002 | R10: 0.07529319 | S10: 0.078468949 | AF10: =+Tabella4[[#This Row],[Inlet]]*Tabella4[[#This Row],[NC]] -> 0.090625894 | AG10: =+Tabella4[[#This Row],[Primary]]*Tabella4[[#This Row],[NC]] -> 0.2086294 | AH10: =+Tabella4[[#This Row],[Secondary]]*Tabella4[[#This Row],[NC]] -> 0.27104015
C11: C4-IP | D11: 4 | E11: =+Inlet!D13 -> 6.568806e-05 | F11: =+Secondary!B9 -> 8.7688471e-05 | G11: =+Outlet!D13 -> 0.00010153019 | J11: 4 | K11: 0.077415623 | L11: 0.10157841 | M11: 0.11453061 | P11: 4 | Q11: 0.077415623 | R11: 0.10157841 | S11: 0.11453061 | AF11: =+Tabella4[[#This Row],[Inlet]]*Tabella4[[#This Row],[NC]] -> 0.00026275224 | AG11: =+Tabella4[[#This Row],[Primary]]*Tabella4[[#This Row],[NC]] -> 0.00035075388 | AH11: =+Tabella4[[#This Row],[Secondary]]*Tabella4[[#This Row],[NC]] -> 0.00040612075
C12: C4-O | D12: 4 | E12: =+Inlet!D14 -> 8.1154749e-23 | F12: =+Secondary!B10 -> 8.1154749e-23 | G12: =+Outlet!D14 -> 8.1154749e-23 | J12: 5 | K12: 0.045335741 | L12: 0.083012932 | M12: 0.098308714 | P12: 5 | Q12: 0.045335741 | R12: 0.083012932 | S12: 0.098308714 | AF12: =+Tabella4[[#This Row],[Inlet]]*Tabella4[[#This Row],[NC]] -> 3.24619e-22 | AG12: =+Tabella4[[#This Row],[Primary]]*Tabella4[[#This Row],[NC]] -> 3.24619e-22 | AH12: =+Tabella4[[#This Row],[Secondary]]*Tabella4[[#This Row],[NC]] -> 3.24619e-22
C13: C5 | D13: 5 | E13: =+Inlet!D15 -> 0.012431187 | F13: =+Secondary!B11 -> 0.041243721 | G13: =+Outlet!D15 -> 0.056768236 | J13: 6 | K13: 0.026864939 | L13: 0.072315339 | M13: 0.088641574 | P13: 6 | Q13: 0.026864939 | R13: 0.072315339 | S13: 0.088641574 | AF13: =+Tabella4[[#This Row],[Inlet]]*Tabella4[[#This Row],[NC]] -> 0.062155936 | AG13: =+Tabella4[[#This Row],[Primary]]*Tabella4[[#This Row],[NC]] -> 0.20621861 | AH13: =+Tabella4[[#This Row],[Secondary]]*Tabella4[[#This Row],[NC]] -> 0.28384118
C14: C5-IP | D14: 5 | E14: =+Inlet!D16 -> 0.00079740252 | F14: =+Secondary!B12 -> 0.00079740252 | G14: =+Outlet!D16 -> 0.00079740252 | J14: 7 | K14: 0.0095802012 | L14: 0.062310421 | M14: 0.079375486 | P14: 7 | Q14: 0.0095802012 | R14: 0.062310421 | S14: 0.079375486 | AF14: =+Tabella4[[#This Row],[Inlet]]*Tabella4[[#This Row],[NC]] -> 0.0039870126 | AG14: =+Tabella4[[#This Row],[Primary]]*Tabella4[[#This Row],[NC]] -> 0.0039870126 | AH14: =+Tabella4[[#This Row],[Secondary]]*Tabella4[[#This Row],[NC]] -> 0.0039870126
C15: C5-O | D15: 5 | E15: =+Inlet!D17 -> 4.9454121e-20 | F15: =+Secondary!B13 -> 4.9454121e-20 | G15: =+Outlet!D17 -> 4.9454121e-20 | J15: 8 | K15: 0.0056977933 | L15: 0.060047293 | M15: 0.076265263 | P15: 8 | Q15: 0.0056977933 | R15: 0.060047293 | S15: 0.076265263 | AF15: =+Tabella4[[#This Row],[Inlet]]*Tabella4[[#This Row],[NC]] -> 2.472706e-19 | AG15: =+Tabella4[[#This Row],[Primary]]*Tabella4[[#This Row],[NC]] -> 2.472706e-19 | AH15: =+Tabella4[[#This Row],[Secondary]]*Tabella4[[#This Row],[NC]] -> 2.472706e-19
C16: C5-N | D16: 5 | E16: =+Inlet!D18 -> 7.7846205e-05 | F16: =+Secondary!B14 -> 7.7846205e-05 | G16: =+Outlet!D18 -> 7.7846205e-05 | J16: 9 | K16: 0.0018885224 | L16: 0.057845045 | M16: 0.072780355 | P16: 9 | Q16: 0.0018885224 | R16: 0.057845045 | S16: 0.072780355 | AF16: =+Tabella4[[#This Row],[Inlet]]*Tabella4[[#This Row],[NC]] -> 0.00038923102 | AG16: =+Tabella4[[#This Row],[Primary]]*Tabella4[[#This Row],[NC]] -> 0.00038923102 | AH16: =+Tabella4[[#This Row],[Secondary]]*Tabella4[[#This Row],[NC]] -> 0.00038923102
C17: C6-IP | D17: 6 | E17: =+Inlet!D19 -> 0.0029408236 | F17: =+Secondary!B15 -> 0.0029408236 | G17: =+Outlet!D19 -> 0.0029408236 | J17: 10 | K17: 0.00035933851 | L17: 0.056968528 | M17: 0.06983842 | P17: 10 | Q17: 0.00035933851 | R17: 0.056968528 | S17: 0.06983842 | AF17: =+Tabella4[[#This Row],[Inlet]]*Tabella4[[#This Row],[NC]] -> 0.017644942 | AG17: =+Tabella4[[#This Row],[Primary]]*Tabella4[[#This Row],[NC]] -> 0.017644942 | AH17: =+Tabella4[[#This Row],[Secondary]]*Tabella4[[#This Row],[NC]] -> 0.017644942
C18: C6 | D18: 6 | E18: =+Inlet!D20 -> 0.0047346599 | F18: =+Secondary!B16 -> 0.033540808 | G18: =+Outlet!D20 -> 0.048824706 | J18: 11 | K18: 2.5611346e-05 | L18: 0.056776401 | M18: 0.0666415 | P18: 11 | Q18: 2.5611346e-05 | R18: 0.056776401 | S18: 0.0666415 | AF18: =+Tabella4[[#This Row],[Inlet]]*Tabella4[[#This Row],[NC]] -> 0.028407959 | AG18: =+Tabella4[[#This Row],[Primary]]*Tabella4[[#This Row],[NC]] -> 0.20124485 | AH18: =+Tabella4[[#This Row],[Secondary]]*Tabella4[[#This Row],[NC]] -> 0.29294824
C19: C6-O | D19: 6 | E19: =+Inlet!D21 -> 1.6313192e-17 | F19: =+Secondary!B17 -> 1.6313192e-17 | G19: =+Outlet!D21 -> 1.6313192e-17 | J19: 12 | K19: 2.3827531e-05 | L19: 0.056755616 | M19: 0.062578843 | P19: 12 | Q19: 2.3827531e-05 | R19: 0.056755616 | S19: 0.062578843 | AF19: =+Tabella4[[#This Row],[Inlet]]*Tabella4[[#This Row],[NC]] -> 9.7879154e-17 | AG19: =+Tabella4[[#This Row],[Primary]]*Tabella4[[#This Row],[NC]] -> 9.7879154e-17 | AH19: =+Tabella4[[#This Row],[Secondary]]*Tabella4[[#This Row],[NC]] -> 9.7879154e-17
... C34: C9-O | D34: 9 | E34: =+Inlet!D36 -> 2.8889358e-11 | F34: =+Secondary!B32 -> 2.8449275e-11 | G34: =+Outlet!D36 -> 2.8015896e-11 | J34: 27 | K34: 0.03478317 | L34: 0 | M34: 0 | P34: 27 | Q34: 0.03478317 | R34: 0 | S34: 0 | AF34: =+Tabella4[[#This Row],[Inlet]]*Tabella4[[#This Row],[NC]] -> 2.6000423e-10 | AG34: =+Tabella4[[#This Row],[Primary]]*Tabella4[[#This Row],[NC]] -> 2.5604347e-10 | AH34: =+Tabella4[[#This Row],[Secondary]]*Tabella4[[#This Row],[NC]] -> 2.5214306e-10
C35: C9-N | D35: 9 | E35: =+Inlet!D37 -> 8.4212848e-05 | F35: =+Secondary!B33 -> 8.4212848e-05 | G35: =+Outlet!D37 -> 8.4212848e-05 | J35: Totale complessivo | K35: 1 | L35: 1 | M35: 1 | AF35: =+Tabella4[[#This Row],[Inlet]]*Tabella4[[#This Row],[NC]] -> 0.00075791563 | AG35: =+Tabella4[[#This Row],[Primary]]*Tabella4[[#This Row],[NC]] -> 0.00075791563 | AH35: =+Tabella4[[#This Row],[Secondary]]*Tabella4[[#This Row],[NC]] -> 0.00075791563
C36: C9-A | D36: 9 | E36: =+Inlet!D38 -> 6.2978784e-09 | F36: =+Secondary!B34 -> 6.2978784e-09 | G36: =+Outlet!D38 -> 6.2978784e-09 | AF36: =+Tabella4[[#This Row],[Inlet]]*Tabella4[[#This Row],[NC]] -> 5.6680905e-08 | AG36: =+Tabella4[[#This Row],[Primary]]*Tabella4[[#This Row],[NC]] -> 5.6680905e-08 | AH36: =+Tabella4[[#This Row],[Secondary]]*Tabella4[[#This Row],[NC]] -> 5.6680905e-08
C37: C10 | D37: 10 | E37: =+Inlet!D39 -> 5.3126266e-05 | F37: =+Secondary!B35 -> 0.028853411 | G37: =+Outlet!D39 -> 0.040899806 | AF37: =+Tabella4[[#This Row],[Inlet]]*Tabella4[[#This Row],[NC]] -> 0.00053126266 | AG37: =+Tabella4[[#This Row],[Primary]]*Tabella4[[#This Row],[NC]] -> 0.28853411 | AH37: =+Tabella4[[#This Row],[Secondary]]*Tabella4[[#This Row],[NC]] -> 0.40899806
C38: C10-IP | D38: 10 | E38: =+Inlet!D40 -> 3.9899902e-05 | F38: =+Secondary!B36 -> 3.8749231e-05 | G38: =+Outlet!D40 -> 3.7631745e-05 | AF38: =+Tabella4[[#This Row],[Inlet]]*Tabella4[[#This Row],[NC]] -> 0.00039899902 | AG38: =+Tabella4[[#This Row],[Primary]]*Tabella4[[#This Row],[NC]] -> 0.00038749231 | AH38: =+Tabella4[[#This Row],[Secondary]]*Tabella4[[#This Row],[NC]] -> 0.00037631745
C39: C10-O | D39: 10 | E39: =+Inlet!D41 -> 2.900543e-08 | F39: =+Secondary!B37 -> 2.8168944e-08 | G39: =+Outlet!D41 -> 2.7356582e-08 | AF39: =+Tabella4[[#This Row],[Inlet]]*Tabella4[[#This Row],[NC]] -> 2.900543e-07 | AG39: =+Tabella4[[#This Row],[Primary]]*Tabella4[[#This Row],[NC]] -> 2.8168944e-07 | AH39: =+Tabella4[[#This Row],[Secondary]]*Tabella4[[#This Row],[NC]] -> 2.7356582e-07
C40: C10-N | D40: 10 | E40: =+Inlet!D42 -> 1.2093808e-05 | F40: =+Secondary!B38 -> 1.2093808e-05 | G40: =+Outlet!D42 -> 1.2093808e-05 | AF40: =+Tabella4[[#This Row],[Inlet]]*Tabella4[[#This Row],[NC]] -> 0.00012093808 | AG40: =+Tabella4[[#This Row],[Primary]]*Tabella4[[#This Row],[NC]] -> 0.00012093808 | AH40: =+Tabella4[[#This Row],[Secondary]]*Tabella4[[#This Row],[NC]] -> 0.00012093808
C41: C10-A | D41: 10 | E41: =+Inlet!D43 -> 3.2000963e-07 | F41: =+Secondary!B39 -> 3.2000963e-07 | G41: =+Outlet!D43 -> 3.2000963e-07 | AF41: =+Tabella4[[#This Row],[Inlet]]*Tabella4[[#This Row],[NC]] -> 3.2000963e-06 | AG41: =+Tabella4[[#This Row],[Primary]]*Tabella4[[#This Row],[NC]] -> 3.2000963e-06 | AH41: =+Tabella4[[#This Row],[Secondary]]*Tabella4[[#This Row],[NC]] -> 3.2000963e-06
C42: C11 | D42: 11 | E42: =+Inlet!D44 -> 6.3675358e-06 | F42: =+Secondary!B40 -> 0.028806019 | G42: =+Outlet!D44 -> 0.03907429 | AF42: =+Tabella4[[#This Row],[Inlet]]*Tabella4[[#This Row],[NC]] -> 7.0042894e-05 | AG42: =+Tabella4[[#This Row],[Primary]]*Tabella4[[#This Row],[NC]] -> 0.31686621 | AH42: =+Tabella4[[#This Row],[Secondary]]*Tabella4[[#This Row],[NC]] -> 0.42981719
C43: C11-IP | D43: 11 | E43: =+Inlet!D45 -> 6.945867e-07 | F43: =+Secondary!B41 -> 6.604575e-07 | G43: =+Outlet!D45 -> 6.2800527e-07 | AF43: =+Tabella4[[#This Row],[Inlet]]*Tabella4[[#This Row],[NC]] -> 7.6404537e-06 | AG43: =+Tabella4[[#This Row],[Primary]]*Tabella4[[#This Row],[NC]] -> 7.2650325e-06 | AH43: =+Tabella4[[#This Row],[Secondary]]*Tabella4[[#This Row],[NC]] -> 6.908058e-06
C44: C11-A | D44: 11 | E44: =+Inlet!D46 -> 1.6555469e-07 | F44: =+Secondary!B42 -> 1.6555469e-07 | G44: =+Outlet!D46 -> 1.6555469e-07 | AF44: =+Tabella4[[#This Row],[Inlet]]*Tabella4[[#This Row],[NC]] -> 1.8211016e-06 | AG44: =+Tabella4[[#This Row],[Primary]]*Tabella4[[#This Row],[NC]] -> 1.8211016e-06 | AH44: =+Tabella4[[#This Row],[Secondary]]*Tabella4[[#This Row],[NC]] -> 1.8211016e-06
C45: C11-O | D45: 11 | E45: =+Inlet!D47 -> 2.8947638e-07 | F45: =+Secondary!B43 -> 2.7525268e-07 | G45: =+Outlet!D47 -> 2.7525268e-07 | AF45: =+Tabella4[[#This Row],[Inlet]]*Tabella4[[#This Row],[NC]] -> 3.1842402e-06 | AG45: =+Tabella4[[#This Row],[Primary]]*Tabella4[[#This Row],[NC]] -> 3.0277795e-06 | AH45: =+Tabella4[[#This Row],[Secondary]]*Tabella4[[#This Row],[NC]] -> 3.0277795e-06
C46: C12-IP | D46: 12 | E46: =+Inlet!D48 -> 1.1504043e-06 | F46: =+Secondary!B44 -> 1.0590443e-06 | G46: =+Outlet!D48 -> 9.7493959e-07 | AF46: =+Tabella4[[#This Row],[Inlet]]*Tabella4[[#This Row],[NC]] -> 1.3804852e-05 | AG46: =+Tabella4[[#This Row],[Primary]]*Tabella4[[#This Row],[NC]] -> 1.2708531e-05 | AH46: =+Tabella4[[#This Row],[Secondary]]*Tabella4[[#This Row],[NC]] -> 1.1699275e-05
C47: C12 | D47: 12 | E47: =+Inlet!D49 -> 5.0522337e-06 | F47: =+Secondary!B45 -> 0.028794736 | G47: =+Outlet!D49 -> 0.036691469 | AF47: =+Tabella4[[#This Row],[Inlet]]*Tabella4[[#This Row],[NC]] -> 6.0626805e-05 | AG47: =+Tabella4[[#This Row],[Primary]]*Tabella4[[#This Row],[NC]] -> 0.34553683 | AH47: =+Tabella4[[#This Row],[Secondary]]*Tabella4[[#This Row],[NC]] -> 0.44029763
... C71: C27 | D71: 27 | E71: =+Inlet!D73 -> 0.010209164 | F71: =+Secondary!B69 -> 0 | G71: =+Outlet!D73 -> 0 | AF71: =+Tabella4[[#This Row],[Inlet]]*Tabella4[[#This Row],[NC]] -> 0.27564744 | AG71: =+Tabella4[[#This Row],[Primary]]*Tabella4[[#This Row],[NC]] -> 0 | AH71: =+Tabella4[[#This Row],[Secondary]]*Tabella4[[#This Row],[NC]] -> 0
D72: 28 | E72: =+Inlet!D74 -> 0 | F72: =+Secondary!B70 -> 0 | G72: =+Outlet!D74 -> 0
D73: 29 | E73: =+Inlet!D75 -> 0 | F73: =+Secondary!B71 -> 0 | G73: =+Outlet!D75 -> 0
D74: 30 | E74: =+Inlet!D76 -> 0 | F74: =+Secondary!B72 -> 0 | G74: =+Outlet!D76 -> 0 | AF74: =+SUM(AF4:AF71) -> 4.9252169 | AG74: =+SUM(AG4:AG71) -> 4.9280422 | AH74: =+SUM(AH4:AH71) -> 4.9280422
D75: 31 | E75: =+Inlet!D77 -> 0 | F75: =+Secondary!B73 -> 0 | G75: =+Outlet!D77 -> 0
D76: 32 | E76: =+Inlet!D78 -> 0 | F76: =+Secondary!B74 -> 0 | G76: =+Outlet!D78 -> 0
D77: 33 | E77: =+Inlet!D79 -> 0 | F77: =+Secondary!B75 -> 0 | G77: =+Outlet!D79 -> 0
D78: 34 | E78: =+Inlet!D80 -> 0 | F78: =+Secondary!B76 -> 0 | G78: =+Outlet!D80 -> 0
D79: 35 | E79: =+Inlet!D81 -> 0 | F79: =+Secondary!B77 -> 0 | G79: =+Outlet!D81 -> 0
...
